Workbook
Name _________HOJ1: #REF!
Name _________HOJ1: #REF!
Name _________HOJ1: #REF!
Name _________HOJ1: #REF!
Name _________HOJ1: #REF!
Name _________HOJ1: #REF!
Name _________HOJ1: #REF!
Name _________HOJ1: #REF!
Name _________HOJ1: #REF!
Name _________HOJ1: #REF!
Name _________HOJ1: #REF!
Name _________HOJ1: #REF!
Name _________HOJ1: #REF!
Name _________HOJ1: #REF!
Name _________HOJ1: #REF!
Name _________HOJ2: #REF!
Name _________HOJ2: #REF!
Name _________HOJ2: #REF!
Name _________HOJ2: #REF!
Name _________HOJ2: #REF!
Name _________HOJ2: #REF!
Name _________HOJ2: #REF!
Name _________HOJ2: #REF!
Name _________HOJ2: #REF!
Name _________HOJ2: #REF!
Name _________HOJ2: #REF!
Name _________HOJ2: #REF!
Name _________HOJ2: #REF!
Name _________HOJ2: #REF!
Name _________HOJ2: #REF!
Name _________HOJ3: #REF!
Name _________HOJ3: #REF!
Name _________HOJ3: #REF!
Name _________HOJ3: #REF!
Name _________HOJ3: #REF!
Name _________HOJ3: #REF!
Name _________HOJ3: #REF!
Name _________HOJ3: #REF!
Name _________HOJ3: #REF!
Name _________HOJ3: #REF!
Name _________HOJ3: #REF!
Name _________HOJ3: #REF!
Name _________HOJ3: #REF!
Name _________HOJ3: #REF!
Name _________HOJ3: #REF!
Name ________HOJ1: #REF!
Name ________HOJ1: #REF!
Name ________HOJ1: #REF!
Name ________HOJ1: #REF!
Name ________HOJ1: #REF!
Name ________HOJ1: #REF!
Name ________HOJ1: #REF!
Name ________HOJ1: #REF!
Name ________HOJ1: #REF!
Name ________HOJ1: #REF!
Name ________HOJ1: #REF!
Name ________HOJ1: #REF!
Name ________HOJ1: #REF!
Name ________HOJ1: #REF!
Name ________HOJ1: #REF!

Sheet Presupuesto Hospital
C6: ITEM | D6: DESCRIPCIÓN | E6: UNID. | F6: CANT. | G6: PRECIO | H6: PARCIAL
D7: COMPONENTE 01: SUFICIENTE Y ADECUADA INFRAESTRUCTURA Y MANTENIMIENTO PARA LA PRESTACIÓN DE SERVICIOS DE SALUD | H7: =+H8+H62+H325+H635+H1139+H1966+H2185+H2232 -> 81030968
B8: X | C8: OE.1 | D8: OBRAS PROVISIONALES, TRABAJOS PRELIMINARES, SEGURIDAD Y SALUD. | H8: =+H9+H52 -> 940011.29 | I8: 940011.29 | J8: =+I8-H8 -> 0
C9: OE.1.1 | D9: OBRAS PROVISIONALES Y TRABAJOS PRELIMINARES | H9: =+H10+H19+H29+H32+H39+H45+H47+H49 -> 541853.9
C10: OE.1.1.1 | D10: CONSTRUCCIONES PROVISIONALES | H10: =SUM(H11:H18) -> 69311.57
C11: OE.1.1.1.1 | D11: Oficinas | E11: m² | F11: 18 | G11: 157.37 | H11: =+ROUND(+IF(F11="",0,F11*G11),2) -> 2832.66
C12: OE.1.1.1.2 | D12: Almacenes | E12: m² | F12: 70 | G12: 109.44 | H12: =+ROUND(+IF(F12="",0,F12*G12),2) -> 7660.8
C13: OE.1.1.1.3 | D13: Casetas de guardianÍa | E13: m² | F13: 10 | G13: 147.84 | H13: =+ROUND(+IF(F13="",0,F13*G13),2) -> 1478.4
C14: OE.1.1.1.5 | D14: Vestuarios | E14: m² | F14: 40 | G14: 130.85 | H14: =+ROUND(+IF(F14="",0,F14*G14),2) -> 5234
C15: OE.1.1.1.6 | D15: Servicios higienicos | E15: m² | F15: 18 | G15: 282.01 | H15: =+ROUND(+IF(F15="",0,F15*G15),2) -> 5076.18
C16: OE.1.1.1.7 | D16: Cercos Provisional de calamina | E16: m | F16: 234 | G16: 53.39 | H16: =+ROUND(+IF(F16="",0,F16*G16),2) -> 12493.26
C17: OE.1.1.1.8 | D17: Cartel de identificación de Obra de 4.80m x 3.60 m | E17: und | F17: 2 | G17: 2517.15 | H17: =+ROUND(+IF(F17="",0,F17*G17),2) -> 5034.3
C18: OE.1.1.1.9 | D18: Suministro e instalacion de equipo para transporte vertical de materiales | E18: gbl | F18: 1 | G18: 29501.97 | H18: =+ROUND(+IF(F18="",0,F18*G18),2) -> 29501.97
C19: OE.1.1.2 | D19: INSTALACIONES PROVISIONALES | H19: =SUM(H20:H28)/2 -> 125356.38
C20: OE.1.1.2.1 | D20: AGUA PARA LA CONSTRUCCIÓN | H20: =SUM(H21) -> 7199.99
C21: OE.1.1.2.1.1 | D21: Almacenamiento y distribución | E21: gbl | F21: 1 | G21: 7199.99 | H21: =+ROUND(+IF(F21="",0,F21*G21),2) -> 7199.99
C22: OE.1.1.2.2 | D22: DESAGÜE PARA LA CONSTRUCCIÓN | H22: =SUM(H23) -> 7199.99
C23: OE.1.1.2.2.1 | D23: Desagüe para la construcción | E23: glb | F23: 1 | G23: 7199.99 | H23: =+ROUND(+IF(F23="",0,F23*G23),2) -> 7199.99
C24: OE.1.1.2.3 | D24: ENERGÍA ELÉCTRICA PROVISIONAL | H24: =SUM(H25) -> 108902.4
C25: OE.1.1.2.3.3 | D25: Servicio extraordinario de energia electrica | E25: mes | F25: 24 | G25: 4537.6 | H25: =+ROUND(+IF(F25="",0,F25*G25),2) -> 108902.4
C26: OE.1.1.2.4 | D26: INSTALACIÓN TELEFÓNICA Y COMUNICACIÓN PROVISIONAL | H26: =SUM(H27:H28) -> 2054
C27: OE.1.1.2.4.1 | D27: Conexion e Instalación | E27: glb | F27: 1 | G27: 520 | H27: =+ROUND(+IF(F27="",0,F27*G27),2) -> 520
C28: OE.1.1.2.4.2 | D28: Consumo y mantenimiento | E28: glb | F28: 1 | G28: 1534 | H28: =+ROUND(+IF(F28="",0,F28*G28),2) -> 1534
C29: OE.1.1.4 | D29: ELIMINACIÓN DE OBSTRUCCIONES | H29: =SUM(H30:H31) -> 298.27
C30: OE.1.1.4.1 | D30: Tala de Arboles | E30: und | F30: 7 | G30: 17.72 | H30: =+ROUND(+IF(F30="",0,F30*G30),2) -> 124.04
C31: OE.1.1.4.2 | D31: Eliminación de Raices | E31: und | F31: 7 | G31: 24.89 | H31: =+ROUND(+IF(F31="",0,F31*G31),2) -> 174.23
C32: OE.1.1.5 | D32: REMOCIONES | H32: =SUM(H33:H38) -> 22288.74
C33: OE.1.1.5.1 | D33: Remoción de Puertas | E33: und | F33: 113 | G33: 23.64 | H33: =+ROUND(+IF(F33="",0,F33*G33),2) -> 2671.32
C34: OE.1.1.5.2 | D34: Remoción de Ventanas | E34: und | F34: 123 | G34: 23.64 | H34: =+ROUND(+IF(F34="",0,F34*G34),2) -> 2907.72
C35: OE.1.1.5.3 | D35: Remoción de Aparatos Sanitarios | E35: und | F35: 35 | G35: 25.21 | H35: =+ROUND(+IF(F35="",0,F35*G35),2) -> 882.35
C36: OE.1.1.5.4 | D36: Remoción de Tijerales de madera | E36: und | F36: 77 | G36: 47.28 | H36: =+ROUND(+IF(F36="",0,F36*G36),2) -> 3640.56
C37: OE.1.1.5.5 | D37: Remoción de Cobertura | E37: m² | F37: 2540.97 | G37: 4.73 | H37: =+ROUND(+IF(F37="",0,F37*G37),2) -> 12018.79
C38: OE.1.1.5.6 | D38: Remoción de Estructuras Metálicas | E38: m² | F38: 50 | G38: 3.36 | H38: =+ROUND(+IF(F38="",0,F38*G38),2) -> 168
C39: OE.1.1.6 | D39: DEMOLICIONES | H39: =SUM(H40:H44) -> 261717.22
C40: OE.1.1.6.1 | D40: Demolicion de muros de ladrillo incluye cimentaciones | E40: m³ | F40: 596.35 | G40: 19.99 | H40: =+ROUND(+IF(F40="",0,F40*G40),2) -> 11921.04
C41: OE.1.1.6.2 | D41: Demolicion de muros de adobe incluye cimentaciones | E41: m³ | F41: 127.38 | G41: 63.64 | H41: =+ROUND(+IF(F41="",0,F41*G41),2) -> 8106.46
C42: OE.1.1.6.3 | D42: DEMOLICIONES DE MUROS DE CONTENCION DE PIEDRA INC. CIMENTACIONES | E42: m³ | F42: 434.35 | G42: 173.49 | H42: =+ROUND(+IF(F42="",0,F42*G42),2) -> 75355.38
C43: OE.1.1.6.4 | D43: Demolicion de Pisos y falso pisos - Manual | E43: m² | F43: 474.2 | G43: 16.77 | H43: =+ROUND(+IF(F43="",0,F43*G43),2) -> 7952.33
C44: OE.1.1.6.5 | D44: Eliminación de Demoliciones | E44: m³ | F44: 1668.76 | G44: 94.91 | H44: =+ROUND(+IF(F44="",0,F44*G44),2) -> 158382.01
C45: OE.1.1.7 | D45: MOVILIZACIÓN DE CAMPAMENTO, MAQUINARIA Y HERRAMIENTAS | H45: =SUM(H46) -> 2400
...

Sheet Presupuesto Contingencia
C6: Item | D6: DESCRIPCION | E6: Und | F6: Metrado | G6: PU | H6: Parcial
B7: X | C7: OE.1 | D7: OBRAS PROVISIONALES, TRABAJOS PRELIMINARES, SEGURIDAD Y SALUD. | H7: =+H8+H25 -> 174052.15 | I7: 174052.15 | J7: =+I7-H7 -> 0
C8: OE.1.1 | D8: OBRAS PROVISIONALES Y TRABAJOS PRELIMINARES | H8: =+H9+H13+H16+H19+H22 -> 114613.09
C9: OE.1.1.1 | D9: CONSTRUCCIONES PROVISIONALES | H9: =SUM(H10:H12) -> 10491.66
C10: OE.1.1.1.1 | D10: Almacén Oficina y Caseta de Guardiania | E10: m2 | F10: 58 | G10: 80.81 | H10: =+ROUND(+IF(F10="",0,F10*G10),2) -> 4686.98
C11: OE.1.1.1.6 | D11: Servicios higienicos | E11: m2 | F11: 31 | G11: 165.45 | H11: =+ROUND(+IF(F11="",0,F11*G11),2) -> 5128.95
C12: OE.1.1.1.8 | D12: Cartel de Obra de 2.40X3.60 | E12: und | F12: 1 | G12: 675.73 | H12: =+ROUND(+IF(F12="",0,F12*G12),2) -> 675.73
C13: OE.1.1.2 | D13: INSTALACIONES PROVISIONALES | H13: =SUM(H14:H15) -> 4292.1
C14: OE.1.1.2.3 | D14: Energia Electrica Provisional | E14: glb | F14: 1 | G14: 2824.9 | H14: =+ROUND(+IF(F14="",0,F14*G14),2) -> 2824.9
C15: OE.1.1.2.4 | D15: Abastecimiento Provisional de agua | E15: glb | F15: 1 | G15: 1467.2 | H15: =+ROUND(+IF(F15="",0,F15*G15),2) -> 1467.2
C16: OE.1.1.3 | D16: TRABAJOS PRELIMINARES | H16: =SUM(H17:H18)/2 -> 23350.92
C17: OE.1.1.3.1 | D17: LIMPIEZA DE TERRENO | H17: =SUM(H18) -> 23350.92
C18: OE.1.1.3.1.1 | D18: Eliminación de maleza y arbustos de fácil extracción | E18: m2 | F18: 1737.42 | G18: 13.44 | H18: =+ROUND(+IF(F18="",0,F18*G18),2) -> 23350.92
C19: OE.1.1.7 | D19: MOVILIZACIÓN DE CAMPAMENTO, MAQUINARIA Y HERRAMIENTAS | H19: =SUM(H20:H21) -> 61068.65
C20: OE.1.1.7.1 | D20: Movilización y desmovilización de equipos | E20: glb | F20: 1 | G20: 1868.65 | H20: =+ROUND(+IF(F20="",0,F20*G20),2) -> 1868.65
C21: OE.1.1.7.2 | D21: Flete Terrestre | E21: glb | F21: 1 | G21: 59200 | H21: =+ROUND(+IF(F21="",0,F21*G21),2) -> 59200
C22: OE.1.1.9 | D22: TRAZOS, NIVELES Y REPLANTEO | H22: =SUM(H23:H24) -> 15409.76
C23: OE.1.1.9.1 | D23: Trazo, niveles y replanteo preliminar | E23: m2 | F23: 3081.95 | G23: 1.1 | H23: =+ROUND(+IF(F23="",0,F23*G23),2) -> 3390.15
C24: OE.1.1.9.2 | D24: Trazo y Replanteo durante el proceso | E24: m2 | F24: 3081.95 | G24: 3.9 | H24: =+ROUND(+IF(F24="",0,F24*G24),2) -> 12019.61
C25: OE.1.2 | D25: SEGURIDAD Y SALUD | H25: =+H26+H32+H35 -> 59439.06
C26: OE.1.2.1 | D26: ELABORACIÓN, IMPLEMENTACIÓN Y ADMINISTRACIÓN DEL PLAN DE SEGURIDAD Y SALUD EN EL TRABAJO | H26: =SUM(H27:H31) -> 33836.29
C27: OE.1.2.1.1 | D27: Elaboracion, Implementacion y administracion del Plan de Seguridad y Salud en el Trabajo | E27: glb | F27: 1 | G27: 3000 | H27: =+ROUND(+IF(F27="",0,F27*G27),2) -> 3000
C28: OE.1.2.1.2 | D28: Equipos de Proteccion Individual | E28: und | F28: 60 | G28: 358.21 | H28: =+ROUND(+IF(F28="",0,F28*G28),2) -> 21492.6
C29: OE.1.2.1.3 | D29: Equipos de Proteccion Colectiva | E29: glb | F29: 1 | G29: 3832.98 | H29: =+ROUND(+IF(F29="",0,F29*G29),2) -> 3832.98
C30: OE.1.2.1.4 | D30: Señalizacion Temporal de Seguridad | E30: glb | F30: 1 | G30: 4349.72 | H30: =+ROUND(+IF(F30="",0,F30*G30),2) -> 4349.72
C31: OE.1.2.1.5 | D31: Capacitacion en Seguridad y Salud | E31: glb | F31: 1 | G31: 1160.99 | H31: =+ROUND(+IF(F31="",0,F31*G31),2) -> 1160.99
C32: OE.1.2.2 | D32: RECURSOS PARA RESPUESTAS ANTE EMERGENCIAS EN SEGURIDAD Y SALUD DURANTE EL TRABAJO | H32: =SUM(H33:H34) -> 4760.06
C33: OE.1.2.2.1 | D33: Equipos de Primeros Auxilios y de Socorro | E33: glb | F33: 1 | G33: 1590.01 | H33: =+ROUND(+IF(F33="",0,F33*G33),2) -> 1590.01
C34: OE.1.2.2.2 | D34: Equipos contra incendios | E34: glb | F34: 1 | G34: 3170.05 | H34: =+ROUND(+IF(F34="",0,F34*G34),2) -> 3170.05
C35: OE.1.2.3 | D35: PLAN PARA LA VIGILANCIA PREVENCION Y CONTROL DE COVID EN EL TRABAJO | H35: =SUM(H36:H40) -> 20842.71
C36: OE.1.2.3.1 | D36: Plan para la vigilancia prevención y control de COVID en el trabajo | E36: und | F36: 1 | G36: 2499.99 | H36: =+ROUND(+IF(F36="",0,F36*G36),2) -> 2499.99
C37: OE.1.2.3.2 | D37: Equipos de Proteccion Individual -Covid19 | E37: und | F37: 60 | G37: 71.42 | H37: =+ROUND(+IF(F37="",0,F37*G37),2) -> 4285.2
C38: OE.1.2.3.3 | D38: Equipos de Proteccion Colectivo ante el COVID-19 | E38: glb | F38: 1 | G38: 2896.72 | H38: =+ROUND(+IF(F38="",0,F38*G38),2) -> 2896.72
C39: OE.1.2.3.4 | D39: Señalización temporal de seguridad ante el COVID-19 | E39: glb | F39: 1 | G39: 660.8 | H39: =+ROUND(+IF(F39="",0,F39*G39),2) -> 660.8
C40: OE.1.2.3.5 | D40: Servicio de Pruebas COVID - 19 | E40: und | F40: 60 | G40: 175 | H40: =+ROUND(+IF(F40="",0,F40*G40),2) -> 10500
B41: X | C41: OE.2 | D41: ESTRUCTURAS. | H41: =+H42+H58+H63+H84+H106 -> 2695167.6 | I41: 2695167.6 | J41: =+I41-H41 -> 0
C42: OE.2.1 | D42: MOVIMIENTO DE TIERRAS | H42: =+H43+H45+H49+H52+H55 -> 313990.51
C43: OE.2.1.1 | D43: EXCAVACIONES MASIVA | H43: =SUM(H44) -> 7815.21
C44: OE.2.1.1.1 | D44: Excavacion con maquinaria | E44: m3 | F44: 1662.81 | G44: 4.7 | H44: =+ROUND(+IF(F44="",0,F44*G44),2) -> 7815.21
C45: OE.2.1.2 | D45: EXCAVACIONES | H45: =SUM(H46:H48)/2 -> 7917.4
...

Sheet MM-1
B3: MAYORES METRADOS N°1
B5: Item | C5: DESCRIPCION | D5: Und | E5: Metrado | F5: PU | G5: Parcial
B6: OE.1 | C6: OBRAS PROVISIONALES, TRABAJOS PRELIMINARES, SEGURIDAD Y SALUD._x000D_ | G6: =+G7 -> 39430.86
B7: OE.1.1 | C7: OBRAS PROVISIONALES Y TRABAJOS PRELIMINARES | G7: =+G8+G12 -> 39430.86
B8: OE.1.1.1 | C8: CONSTRUCCIONES PROVISIONALES | G8: =SUM(G9:G11) -> 23759.82
B9: OE.1.1.1.1 | C9: Almacén Oficina y Caseta de Guardiania | D9: m2 | E9: 214 | F9: 80.81 | G9: =+ROUND(E9*F9,2) -> 17293.34
B10: OE.1.1.1.6 | C10: Servicios higienicos | D10: m2 | E10: 35 | F10: 165.45 | G10: =+ROUND(E10*F10,2) -> 5790.75
B11: OE.1.1.1.8 | C11: Cartel de Obra de 2.40X3.60 | D11: und | E11: 1 | F11: 675.73 | G11: =+ROUND(E11*F11,2) -> 675.73
B12: OE.1.1.3 | C12: TRABAJOS PRELIMINARES | G12: =SUM(G13:G14)/2 -> 15671.04
B13: OE.1.1.3.1 | C13: LIMPIEZA DE TERRENO | G13: =SUM(G14) -> 15671.04
B14: OE.1.1.3.1.1 | C14: Eliminación de maleza y arbustos de fácil extracción | D14: m2 | E14: 1166 | F14: 13.44 | G14: =+ROUND(E14*F14,2) -> 15671.04
B15: OE.2 | C15: ESTRUCTURAS | G15: =+G16 -> 7126.54
B16: OE.2.1 | C16: MOVIMIENTO DE TIERRAS | G16: =+G17+G19 -> 7126.54
B17: OE.2.1.5. | C17: NIVELACION INTERIOR Y APISONADO | G17: =SUM(G18) -> 5622.75
B18: OE.2.1.5.1 | C18: Nivelacion interior y apisonado para f.piso,patio y veredas | D18: m2 | E18: 1275 | F18: 4.41 | G18: =+ROUND(E18*F18,2) -> 5622.75
B19: OE.2.6.5 | C19: CONTROL DE CALIDAD | G19: =SUM(G20:G21) -> 1503.79
B20: OE.2.6.5.4 | C20: Rotura de Briquetas de concreto | D20: und | E20: 14 | F20: 50 | G20: =+ROUND(E20*F20,2) -> 700
B21: OE.2.6.5.5 | C21: Pruebas de soldadura | D21: und | E21: 27 | F21: 29.77 | G21: =+ROUND(E21*F21,2) -> 803.79
B22: OE.3 | C22: ARQUITECTURA | G22: =+G23+G26 -> 74554.92
B23: OE.3.3 | C23: CIELORRASOS | G23: =+G24 -> 22653.34
B24: OE.3.3.6 | C24: FALSO CIELO RASO | G24: =SUM(G25) -> 22653.34
B25: OE.3.3.6.1 | C25: FALSO CIELORRASO (BALDOSA DE FIBRA MINERAL BIOSOLUBLE 0.61 x 0.61m, E=14mm.) | D25: m2 | E25: 315.77 | F25: 71.74 | G25: =+ROUND(E25*F25,2) -> 22653.34
B26: OE.3.4 | C26: PISOS Y PAVIMENTOS | G26: =+G27 -> 51901.58
B27: OE.3.4.1 | C27: CONTRAPISOS | G27: =SUM(G28) -> 51901.58
B28: OE.3.4.1.1 | C28: Contrapiso de concreto f'c=175 kg/cm2 e =5 cm | D28: m2 | E28: 1716.89 | F28: 30.23 | G28: =+ROUND(E28*F28,2) -> 51901.58
C29: TOTAL | G29: =+G22+G15+G6 -> 121112.32
G31: 121112.32
G32: =+G31-G29 -> 0

Sheet PN-1
B3: PARTIDAS NUEVAS N°1
B5: Item | C5: DESCRIPCION | D5: Und | E5: Metrado | F5: PU | G5: Parcial
B6: OE.1 | C6: OBRAS PROVISIONALES, TRABAJOS PRELIMINARES, SEGURIDAD Y SALUD._x000D_ | G6: =+G7 -> 132711.56
B7: OE.1.1 | C7: OBRAS PROVISIONALES Y TRABAJOS PRELIMINARES | G7: =+G8 -> 132711.56
B8: OE.1.1.3 | C8: TRABAJOS PRELIMINARES | G8: =SUM(G9:G13)/2 -> 132711.56
B9: OE.1.1.3.1 | C9: LIMPIEZA DE TERRENO | G9: =SUM(G10:G13) -> 132711.56
B10: OE.1.1.3.1.2 | C10: Traslado de material en desuso d=100 m | D10: m3 | E10: 1916 | F10: 40.45 | G10: =+ROUND(E10*F10,2) -> 77502.2
B11: OE.1.1.3.1.3 | C11: Limpieza de terreno | D11: m2 | E11: 3002 | F11: 2.61 | G11: =+ROUND(E11*F11,2) -> 7835.22
B12: OE.1.1.3.1.4 | C12: Acarreo manual de material de desmonte | D12: m3 | E12: 802 | F12: 25.21 | G12: =+ROUND(E12*F12,2) -> 20218.42
B13: OE.1.1.3.1.5 | C13: Eliminacion de desmonte con maquinaria | D13: m3 | E13: 802 | F13: 33.86 | G13: =+ROUND(E13*F13,2) -> 27155.72
B14: OE.2 | C14: ESTRUCTURAS. | G14: =+G15+G19+G32+G62 -> 1683126.1
B15: OE.2.2 | C15: OBRAS DE CONCRETO SIMPLE | G15: =+G16 -> 58685.18
B16: OE.2.2.4 | C16: DADOS DE ANCLAJE | G16: =SUM(G17:G18) -> 58685.18
B17: OE.2.2.4.1 | C17: Dado de anclaje f'c= 210 kg/cm2 | D17: und | E17: 337 | F17: 72.23 | G17: =+ROUND(E17*F17,2) -> 24341.51
B18: OE.2.2.4.2 | C18: Acero en dado de anclaje para cimientos de columna | D18: kg | E18: 1011 | F18: 33.97 | G18: =+ROUND(E18*F18,2) -> 34343.67
B19: OE.2.3 | C19: OBRAS DE CONCRETO ARMADO | G19: =+G20+G25+G29 -> 401553.45
B20: OE.2.3.9 | C20: LOSAS | G20: =SUM(G21:G24)/2 -> 203103.08
B21: OE.2.3.9.8 | C21: LOSAS DE CONCRETO | G21: =SUM(G22:G24) -> 203103.08
B22: OE.2.3.9.8.1 | C22: Concreto f'c=210 kg/cm2 en losa | D22: m3 | E22: 294.95 | F22: 466.32 | G22: =+ROUND(E22*F22,2) -> 137541.08
B23: OE.2.3.9.8.2 | C23: Encofrado y desencofrado en losa de concreto | D23: m2 | E23: 98.09 | F23: 65.1 | G23: =+ROUND(E23*F23,2) -> 6385.66
B24: OE.2.3.9.8.3 | C24: Acero f'y=4200 kg/cm2 en losa de concreto | D24: kg | E24: 8084.2 | F24: 7.32 | G24: =+ROUND(E24*F24,2) -> 59176.34
B25: OE.2.3.13 | C25: SOBRECIMIENTO ARMADO | G25: =SUM(G26:G28) -> 23310.4
B26: OE.2.3.13.1 | C26: Sobrecimiento concreto 1:8+25%PM | D26: m3 | E26: 16.9 | F26: 328.51 | G26: =+ROUND(E26*F26,2) -> 5551.82
B27: OE.2.3.13.2 | C27: Encofrado y desencofrado en sobrecimiento | D27: m2 | E27: 242.48 | F27: 67.61 | G27: =+ROUND(E27*F27,2) -> 16394.07
B28: OE.2.3.13.3 | C28: Acero f'y=4200 kg/cm2 en sobrecimiento | D28: kg | E28: 489.07 | F28: 2.79 | G28: =+ROUND(E28*F28,2) -> 1364.51
B29: OE.2.3.14 | C29: CIMIENTO CORRIDO | G29: =SUM(G30:G31) -> 175139.97
B30: OE.2.3.14.1 | C30: Concreto f'c= 175 kg/cm2 en cimiento | D30: m3 | E30: 135.21 | F30: 379.99 | G30: =+ROUND(E30*F30,2) -> 51378.45
B31: OE.2.3.14.2 | C31: Encofrado y desencofrado en cimiento | D31: m2 | E31: 387.36 | F31: 319.5 | G31: =+ROUND(E31*F31,2) -> 123761.52
B32: OE.2.4 | C32: ESTRUCTURAS METÁLICAS | G32: =+G33+G37+G41 -> 1134817.5
B33: OE.2.4.1 | C33: COLUMNAS METALICAS | G33: =SUM(G34:G36) -> 320358.96
B34: OE.2.4.1.1.7 | C34: Placa Base Inc. Pernos de anclaje | D34: und | E34: 337 | F34: 160.83 | G34: =+ROUND(E34*F34,2) -> 54199.71
B35: OE.2.4.1.1.8 | C35: Armado Columnas metálicas 150x100x4mm (L=6m) | D35: kg | E35: 17685 | F35: 11.46 | G35: =+ROUND(E35*F35,2) -> 202670.1
B36: OE.2.4.1.1.9 | C36: Montaje Columnas metálicas 150x100x4mm (L=6m) | D36: kg | E36: 17685 | F36: 3.59 | G36: =+ROUND(E36*F36,2) -> 63489.15
B37: OE.2.4.2 | C37: VIGAS METALICAS | G37: =SUM(G38:G40) -> 298945.7
B38: OE.2.4.2.2.2.5 | C38: Plancha Metalica Inc.Pernos de sujeción | D38: und | E38: 337 | F38: 136.23 | G38: =+ROUND(E38*F38,2) -> 45909.51
B39: OE.2.4.2.2.2.6 | C39: Armado vigas metálicas 150x100mm e= 3mm | D39: m | E39: 927.45 | F39: 201.95 | G39: =+ROUND(E39*F39,2) -> 187298.53
B40: OE.2.4.2.2.2.7 | C40: Montaje vigas metálicas 150x100 mm e=3mm | D40: m | E40: 927.45 | F40: 70.88 | G40: =+ROUND(E40*F40,2) -> 65737.66
B41: OE.2.4.3 | C41: TIJERALES METALICO | G41: =SUM(G42:G61)/2 -> 515512.85
B42: OE.2.4.3.2 | C42: Armado de Tijeral Metalico | G42: =SUM(G43:G50) -> 285585.65
B43: OE.2.4.3.2.1 | C43: Armado de Tijeral metalico Tipo 01 L=7.00 m | D43: und | E43: 28 | F43: 2166.84 | G43: =+ROUND(E43*F43,2) -> 60671.52
...

Sheet DD-1
B4: DEDUCTIVOS
B6: Item | C6: Descripción | D6: Und. | E6: Metrado | F6: Precio S/. | G6: Parcial S/.
B7: OE.2 | C7: ESTRUCTURAS. | G7: =+G8+G11+G28+G50 -> 2148901
B8: OE.2.2 | C8: OBRAS DE CONCRETO SIMPLE | G8: =+G9 -> 3117.6
B9: OE.2.2.2 | C9: FALSA ZAPATA | G9: =SUM(G10) -> 3117.6
B10: OE.2.2.2.1 | C10: Falsa zapata, concreto=100kg/cm2 + 50% P.G | D10: m3 | E10: 12 | F10: 259.8 | G10: =+ROUND(E10*F10,2) -> 3117.6
B11: OE.2.3 | C11: OBRAS DE CONCRETO ARMADO | G11: =+G12+G15+G19+G23 -> 177707.51
B12: OE.2.3.2 | C12: ZAPATAS | G12: =SUM(G13:G14) -> 48460.13
B13: OE.2.3.2.1 | C13: Zapatas - Concreto f'c=210 kg/cm2 | D13: m3 | E13: 60.83 | F13: 439.55 | G13: =+ROUND(E13*F13,2) -> 26737.83
B14: OE.2.3.2.3 | C14: Zapatas - Acero f'y=4200 kg/cm2 | D14: kg | E14: 3025.39 | F14: 7.18 | G14: =+ROUND(E14*F14,2) -> 21722.3
B15: OE.2.3.3 | C15: VIGAS DE CIMENTACIÓN | G15: =SUM(G16:G18) -> 60035.73
B16: OE.2.3.3.1 | C16: Vigas de Conexión - Concreto f'c= 210 kg/cm2 | D16: m3 | E16: 40.33 | F16: 456.98 | G16: =+ROUND(E16*F16,2) -> 18430
B17: OE.2.3.3.2 | C17: Vigas de Conexión - Encofrado y desencofrado | D17: m2 | E17: 185.55 | F17: 68.05 | G17: =+ROUND(E17*F17,2) -> 12626.68
B18: OE.2.3.3.3 | C18: Vigas de Conexión - Acero f'y=4200 kg/cm2 | D18: kg | E18: 4036.08 | F18: 7.18 | G18: =+ROUND(E18*F18,2) -> 28979.05
B19: OE.2.3.7 | C19: PEDESTALES | G19: =SUM(G20:G22) -> 15363.33
B20: OE.2.3.7.1 | C20: Pedestales - Concreto f'c=210 kg/cm2 | D20: m3 | E20: 13.81 | F20: 544.15 | G20: =+ROUND(E20*F20,2) -> 7514.71
B21: OE.2.3.7.2 | C21: Pedestales - Encofrado y desencofrado | D21: m2 | E21: 92.43 | F21: 55.68 | G21: =+ROUND(E21*F21,2) -> 5146.5
B22: OE.2.3.7.3 | C22: Pedestales - Acero f'y=4200 kg/cm2 | D22: kg | E22: 376.34 | F22: 7.18 | G22: =+ROUND(E22*F22,2) -> 2702.12
B23: OE.2.3.9 | C23: LOSAS | G23: =SUM(G24:G27)/2 -> 53848.32
B24: OE.2.3.9.7 | C24: LOSAS COLABORANTE | G24: =SUM(G25:G27) -> 53848.32
B25: OE.2.3.9.7.1 | C25: Losa Colaborante - Concreto f'c=210 kg/cm2 | D25: m3 | E25: 29.8 | F25: 475.08 | G25: =+ROUND(E25*F25,2) -> 14157.38
B26: OE.2.3.9.7.2 | C26: Losa colaborante.- PLANCHA AD-900 calibre 22 ó equivalente | D26: m2 | E26: 298.03 | F26: 120.87 | G26: =+ROUND(E26*F26,2) -> 36022.89
B27: OE.2.3.9.7.3 | C27: Losa Colaborante - Acero Fy=4,200 kg/cm2 | D27: kg | E27: 529.3 | F27: 6.93 | G27: =+ROUND(E27*F27,2) -> 3668.05
B28: OE.2.4 | C28: ESTRUCTURAS METÁLICAS | G28: =+G29+G36+G44+G48 -> 1953377.8
B29: OE.2.4.1 | C29: COLUMNAS METALICAS | G29: =SUM(G30:G35) -> 316683.08
B30: OE.2.4.1.1.1 | C30: Columnas metalicas | D30: kg | E30: 24526.69 | F30: 11.58 | G30: =+ROUND(E30*F30,2) -> 284019.07
B31: OE.2.4.1.1.2 | C31: Placa Base | D31: kg | E31: 1249 | F31: 8.89 | G31: =+ROUND(E31*F31,2) -> 11103.61
B32: OE.2.4.1.1.3 | C32: Pernos 1" (L=450mm) en placa base columnas | D32: und | E32: 40 | F32: 104.67 | G32: =+ROUND(E32*F32,2) -> 4186.8
B33: OE.2.4.1.1.4 | C33: Pernos 3/4" (L=450mm) en placa base columnas | D33: und | E33: 68 | F33: 86.1 | G33: =+ROUND(E33*F33,2) -> 5854.8
B34: OE.2.4.1.1.5 | C34: Pernos 5/8" (L=450mm) en placa base columnas | D34: und | E34: 144 | F34: 68.55 | G34: =+ROUND(E34*F34,2) -> 9871.2
B35: OE.2.4.1.1.6 | C35: Pernos ØM16 A490 (L=400mm) en placa base columnas | D35: und | E35: 40 | F35: 41.19 | G35: =+ROUND(E35*F35,2) -> 1647.6
B36: OE.2.4.2 | C36: VIGAS METALICAS | G36: =SUM(G37:G43)-G39 -> 1623087.2
B37: OE.2.4.2.1.1 | C37: Vigas Metalicas | D37: kg | E37: 132790.72 | F37: 10.86 | G37: =+ROUND(E37*F37,2) -> 1442107.2
B38: OE.2.4.2.2.1 | C38: Plancha Metalica | D38: kg | E38: 13273.41 | F38: 6.91 | G38: =+ROUND(E38*F38,2) -> 91719.26
B39: OE.2.4.2.2.2 | C39: PERNOS | G39: =SUM(G40:G43) -> 89260.77
B40: OE.2.4.2.2.2.1 | C40: Pernos 1/2" | D40: und | E40: 1596 | F40: 4.44 | G40: =+ROUND(E40*F40,2) -> 7086.24
B41: OE.2.4.2.2.2.2 | C41: Pernos 5/8" | D41: und | E41: 1897 | F41: 7.59 | G41: =+ROUND(E41*F41,2) -> 14398.23
B42: OE.2.4.2.2.2.3 | C42: Pernos 3/4" | D42: und | E42: 3422 | F42: 11.05 | G42: =+ROUND(E42*F42,2) -> 37813.1
B43: OE.2.4.2.2.2.4 | C43: Pernos 7/8" | D43: und | E43: 1952 | F43: 15.35 | G43: =+ROUND(E43*F43,2) -> 29963.2
B44: OE.2.4.3 | C44: TIJERALES METALICO | G44: =SUM(G45:G47)-G46 -> 8557.52
...

Sheet Compilado de modificaciones
A1: ITEM | B1: DESCRIPCIÓN | C1: UNIDAD | D1: metrado_programado | E1: valorizacion_programada | F1: metrado_anterior_acumulado | G1: valorizacion_anterior
A2: OE.1 | B2: OBRAS PROVISIONALES, TRABAJOS PRELIMINARES, SEGURIDAD Y SALUD.
A3: OE.1.1 | B3: OBRAS PROVISIONALES Y TRABAJOS PRELIMINARES
A4: OE.1.1.1 | B4: CONSTRUCCIONES PROVISIONALES
A5: OE.1.1.1.1 | B5: Oficinas | C5: m² | D5: 1018 | E5: 160202.66 | F5: 1018 | G5: 160202.66 | I5: =F5/D5 -> 1 | J5: =D5-F5 -> 0
A6: OE.1.1.1.2 | B6: Almacenes | C6: m² | D6: 4368.09 | E6: 478043.77 | F6: 4368.09 | G6: 478043.77 | I6: =F6/D6 -> 1 | J6: =D6-F6 -> 0
A7: OE.1.1.1.3 | B7: Casetas de guardianÍa | C7: m² | D7: 92.53 | E7: 13679.63 | F7: 92.53 | G7: 13679.635 | I7: =F7/D7 -> 1 | J7: =D7-F7 -> 0
A8: OE.1.1.1.5 | B8: Vestuarios | C8: m² | D8: 1420 | E8: 185807 | F8: 1420 | G8: 185807 | I8: =F8/D8 -> 1 | J8: =D8-F8 -> 0
A9: OE.1.1.1.6 | B9: Servicios higienicos | C9: m² | D9: 134 | E9: 37789.34 | F9: 114 | G9: 32149.14 | I9: =F9/D9 -> 0.85074627 | J9: =D9-F9 -> 20
A10: OE.1.1.1.7 | B10: Cercos Provisional de calamina | C10: m | D10: 1432.18 | E10: 76464.09 | F10: 1364.58 | G10: 72854.926 | I10: =F10/D10 -> 0.95279923 | J10: =D10-F10 -> 67.6
A11: OE.1.1.1.8 | B11: Cartel de identificación de Obra de 4.80m x 3.60 m | C11: und | D11: 2 | E11: 5034.3 | F11: 2 | G11: 5034.3 | I11: =F11/D11 -> 1 | J11: =D11-F11 -> 0
A12: OE.1.1.1.9 | B12: Suministro e instalacion de equipo para transporte vertical de materiales | C12: gbl | D12: 1 | E12: 29501.97 | F12: 0 | G12: 0 | I12: =F12/D12 -> 0 | J12: =D12-F12 -> 1
A13: OE.1.1.1.10 | B13: Traslado de material en desuso de Belempampa a Coripata y Antonio Lorena (D=750m) | C13: kg | D13: 110000 | E13: 14300 | F13: 110000 | G13: 14300 | I13: =F13/D13 -> 1 | J13: =D13-F13 -> 0
A14: OE.1.1.1.11 | B14: Traslado de materiales de Belempampa a almacén Huancaro (D=1800m) | C14: kg | D14: 2026138.6 | E14: 607841.59 | F14: 2026138.6 | G14: 607841.59 | I14: =F14/D14 -> 1 | J14: =D14-F14 -> 0
A15: OE.1.1.1.12 | B15: Desmontaje y traslado de módulos prefabricados | C15: und | D15: 7 | E15: 12067.09 | F15: 7 | G15: 12067.09 | I15: =F15/D15 -> 1 | J15: =D15-F15 -> 0
A16: OE.1.1.1.13 | B16: Reubicación manual de material en obra D=300 m-Kilogramos | C16: kg | D16: 1845384.9 | E16: 1365584.9 | F16: 1845384.9 | G16: 1365584.9 | I16: =F16/D16 -> 1 | J16: =D16-F16 -> 0
... A21: OE.1.1.1.18 | B21: Orden y limpieza permanente en obra | C21: mes | D21: 24 | E21: 322135.2 | F21: 18 | G21: 241601.4 | I21: =F21/D21 -> 0.75 | J21: =D21-F21 -> 6
A22: OE.1.1.1.19 | B22: Desmontaje de oficinas y almacenes | C22: m² | D22: 4463.15 | E22: 244312.83 | F22: 4365.65 | G22: 238975.68 | I22: =F22/D22 -> 0.97815444 | J22: =D22-F22 -> 97.5 | L22: 455.5
A23: OE.1.1.1.20 | B23: Almacén de estructura metálica | C23: m² | D23: 890 | E23: 432548.9 | F23: 890 | G23: 432548.9 | I23: =F23/D23 -> 1 | J23: =D23-F23 -> 0
A24: OE.1.1.1.21 | B24: Embalado de materiales de almacén para traslado | C24: kg | D24: 455934.64 | E24: 155017.78 | F24: 420197.83 | G24: 142867.26 | I24: =F24/D24 -> 0.92161857 | J24: =D24-F24 -> 35736.81
A25: OE.1.1.1.22 | B25: Habilitación y nivelación de accesos para maquinaria | C25: m² | D25: 6207.53 | E25: 262888.9 | F25: 5886.88 | G25: 249309.37 | I25: =F25/D25 -> 0.94834499 | J25: =D25-F25 -> 320.65
A26: OE.1.1.1.23 | B26: Habilitación de escantillón y soportes para malla de acero | C26: kg | D26: 17372.49 | E26: 72269.56 | F26: 16852.09 | G26: 70104.694 | I26: =F26/D26 -> 0.97004459 | J26: =D26-F26 -> 520.4
A27: OE.1.1.1.24 | B27: Vaciado de falso piso en ambientes provisionales (almacén, vestuarios, ss.hh y otros) | C27: m² | D27: 627.48 | E27: 30846.92 | F27: 476.48 | G27: 23423.757 | I27: =F27/D27 -> 0.75935488 | J27: =D27-F27 -> 151
A28: OE.1.1.1.25 | B28: Habilitación y colocación de mobiliario de 1.20x0.8m | C28: und | D28: 202 | E28: 77374.08 | F28: 192 | G28: 73543.68 | I28: =F28/D28 -> 0.95049505 | J28: =D28-F28 -> 10
A29: OE.1.1.1.26 | B29: Mantenimiento de andamios y estructuras metálicas | C29: und | D29: 130 | E29: 31584.8 | F29: 88 | G29: 21380.48 | I29: =F29/D29 -> 0.67692308 | J29: =D29-F29 -> 42
A30: OE.1.1.1.27 | B30: PUERTAS PROVISIONALES | E30: 9234.81 | G30: 9234.8137 | J30: =D30-F30 -> 0
A31: OE.1.1.1.27.1 | B31: Instalación de puerta provisional metálica | C31: m² | D31: 55.99 | E31: 4626.45 | F31: 55.99 | G31: 4626.4537 | I31: =F31/D31 -> 1 | J31: =D31-F31 -> 0
A32: OE.1.1.1.27.2 | B32: Instalación de puerta provisional de madera para almacén Huancaro | C32: m² | D32: 102 | E32: 4608.36 | F32: 102 | G32: 4608.36 | I32: =F32/D32 -> 1 | J32: =D32-F32 -> 0
A33: OE.1.1.1.28 | B33: HABILITACION DE MOVILIARIOS PARA OBRA | E33: 112270.86 | G33: 110350.41 | J33: =D33-F33 -> 0
A34: OE.1.1.1.28.1 | B34: Habilitación de mobiliario estante L=1.20m x 1.80m | C34: und | D34: 150 | E34: 41152.5 | F34: 143 | G34: 39232.05 | I34: =F34/D34 -> 0.95333333 | J34: =D34-F34 -> 7
A35: OE.1.1.1.28.2 | B35: Habilitación de pizarra acrílica para obra de 1.20m x 2.40m | C35: und | D35: 43 | E35: 14040.36 | F35: 43 | G35: 14040.36 | I35: =F35/D35 -> 1 | J35: =D35-F35 -> 0
A36: OE.1.1.1.28.3 | B36: Habilitado de estantes para almacén de 2.50m x 0.90m con rollizo | C36: m | D36: 126 | E36: 57078 | F36: 126 | G36: 57078 | I36: =F36/D36 -> 1 | J36: =D36-F36 -> 0
A37: OE.1.1.1.29 | B37: CONSTRUCCIONES METALICAS | E37: 198552.98 | G37: 198552.98 | J37: =D37-F37 -> 0
A38: OE.1.1.1.29.1 | B38: Habilitado y colocado de escalera metálica provisional | C38: kg | D38: 15601.45 | E38: 124343.56 | F38: 15601.45 | G38: 124343.56 | I38: =F38/D38 -> 1 | J38: =D38-F38 -> 0
A39: OE.1.1.1.29.2 | B39: Vestuario de estructura metálica | C39: m² | D39: 100 | E39: 10955 | F39: 100 | G39: 10955 | I39: =F39/D39 -> 1 | J39: =D39-F39 -> 0
A40: OE.1.1.1.29.3 | B40: Habilitado y colocado de puente metálico | C40: kg | D40: 7320.18 | E40: 52412.49 | F40: 7320.18 | G40: 52412.489 | I40: =F40/D40 -> 1 | J40: =D40-F40 -> 0
A41: OE.1.1.1.29.4 | B41: Habilitado de soporte de cámaras de vigilancia móvil | C41: und | D41: 20 | E41: 4026.4 | F41: 20 | G41: 4026.4 | I41: =F41/D41 -> 1 | J41: =D41-F41 -> 0
A42: OE.1.1.1.29.5 | B42: Habilitación de escuadra metálica para soporte en voladizo | C42: kg | D42: 557.28 | E42: 6815.53 | F42: 557.28 | G42: 6815.5344 | I42: =F42/D42 -> 1 | J42: =D42-F42 -> 0
A43: OE.1.1.1.30 | B43: CONSTRUCCIONES PROVISIONALES EN OBRA | E43: 13538.42 | G43: 13402.579 | J43: =D43-F43 -> 0
A44: OE.1.1.1.30.1 | B44: Habilitacion e instalacion de esquineros protectores tipo L | C44: und | D44: 440 | E44: 9961.6 | F44: 434 | G44: 9825.76 | I44: =F44/D44 -> 0.98636364 | J44: =D44-F44 -> 6
...

Sheet Var. MO-2
B1: |
B5: UNIDAD EJECUTORA | C5: : GERENCIA REGIONAL DE GESTION DE INVERSIONES DE INFRAESTRUCTURA - GOBIERNO REGIONAL CUSCO (SEDE CENTRAL)
B6: OBRA | C6: : MEJORAMIENTO Y AMPLIACION DE LOS SERVICIOS DE SALUD DEL ESTABLECIMIENTO DE SALUD DE BELEMPAMPA - DISTRITO DE SANTIAGO - PROVINCIA DE CUSCO - REGION CUSCO
B7: META | C7: : 0119-2025
B9: VARIACION DE MANO DE OBRA N°5
B11: Item | C11: DESCRIPCION | D11: Und | E11: Metrado Expediente | F11: PN1 | G11: MM1 | H11: DD1 | I11: Metrado Actual | J11: P.U. Expediente | K11: Parcial Expediente | L11: P.U. Actualizado | M11: Parcial Actualizado | N11: Diferencia P.U. | O11: Diferencia Parcial | R11: PN1 | S11: MM1 | T11: DD1
A12: x | C12: COMPONENTE 01: SUFICIENTE Y ADECUADA INFRAESTRUCTURA Y MANTENIMIENTO PARA LA PRESTACIÓN DE SERVICIOS DE SALUD | K12: =+K13+K23+K104+K197+K345+K524+K568 -> 4419206.6 | M12: =+M13+M23+M104+M197+M345+M524+M568 -> 4471604.4 | O12: =+O13+O23+O104+O197+O345+O524+O568 -> 52397.73 | R12: =+R13+R23+R104+R197+R345+R524+R568 -> 0 | S12: =+S13+S23+S104+S197+S345+S524+S568 -> 0 | T12: =+T13+T23+T104+T197+T345+T524+T568 -> 0
A13: X | B13: OE.1 | C13: OBRAS PROVISIONALES, TRABAJOS PRELIMINARES, SEGURIDAD Y SALUD. | K13: =+K14 -> 30972.9 | M13: =+M14 -> 31424.51 | O13: =+O14 -> 451.61
B14: OE.1.1 | C14: OBRAS PROVISIONALES Y TRABAJOS PRELIMINARES | K14: =+K15+K21 -> 30972.9 | M14: =+M15+M21 -> 31424.51 | O14: =+O15+O21 -> 451.61 | P14: =+MAX(N14:N572) -> 238.9
B15: OE.1.1.3 | C15: TRABAJOS PRELIMINARES | K15: =SUM(K16:K20)/2 -> 30356.89 | M15: =SUM(M16:M20)/2 -> 30805.35 | O15: =SUM(O16:O20)/2 -> 448.46
B16: OE.1.1.3.1 | C16: LIMPIEZA DE TERRENO | K16: =SUM(K17:K20) -> 30356.89 | M16: =SUM(M17:M20) -> 30805.35 | O16: =SUM(O17:O20) -> 448.46
B17: OE.1.1.3.1.2 | C17: Traslado de material en desuso d=100 m | D17: m3 | F17: 44 | I17: =SUM(E17:H17) -> 44 | J17: 40.45 | K17: =+ROUND(+IF(I17="",0,I17*J17),2) -> 1779.8 | L17: 42.1 | M17: =+ROUND(+IF(I17="",0,I17*L17),2) -> 1852.4 | N17: =+L17-J17 -> 1.65 | O17: =+M17-K17 -> 72.6
B18: OE.1.1.3.1.3 | C18: Limpieza de terreno | D18: m2 | F18: 23 | I18: =SUM(E18:H18) -> 23 | J18: 2.61 | K18: =+ROUND(+IF(I18="",0,I18*J18),2) -> 60.03 | L18: 2.75 | M18: =+ROUND(+IF(I18="",0,I18*L18),2) -> 63.25 | N18: =+L18-J18 -> 0.14 | O18: =+M18-K18 -> 3.22
B19: OE.1.1.3.1.4 | C19: Acarreo manual de material de desmonte | D19: m3 | F19: 54 | I19: =SUM(E19:H19) -> 54 | J19: 25.21 | K19: =+ROUND(+IF(I19="",0,I19*J19),2) -> 1361.34 | L19: 26.17 | M19: =+ROUND(+IF(I19="",0,I19*L19),2) -> 1413.18 | N19: =+L19-J19 -> 0.96 | O19: =+M19-K19 -> 51.84
B20: OE.1.1.3.1.5 | C20: Eliminacion de desmonte con maquinaria | D20: m3 | F20: 802 | I20: =SUM(E20:H20) -> 802 | J20: 33.86 | K20: =+ROUND(+IF(I20="",0,I20*J20),2) -> 27155.72 | L20: 34.26 | M20: =+ROUND(+IF(I20="",0,I20*L20),2) -> 27476.52 | N20: =+L20-J20 -> 0.4 | O20: =+M20-K20 -> 320.8
B21: OE.1.1.9 | C21: TRAZOS, NIVELES Y REPLANTEO | K21: =SUM(K22) -> 616.01 | M21: =SUM(M22) -> 619.16 | O21: =SUM(O22) -> 3.15
B22: OE.1.1.9.2 | C22: Trazo y Replanteo durante el proceso | D22: m2 | E22: 157.95 | I22: =SUM(E22:H22) -> 157.95 | J22: 3.9 | K22: =+ROUND(+IF(I22="",0,I22*J22),2) -> 616.01 | L22: 3.92 | M22: =+ROUND(+IF(I22="",0,I22*L22),2) -> 619.16 | N22: =+L22-J22 -> 0.02 | O22: =+M22-K22 -> 3.15
A23: X | B23: OE.2 | C23: ESTRUCTURAS. | K23: =+K24+K37+K43+K60+K91 -> 1590221.6 | M23: =+M24+M37+M43+M60+M91 -> 1607750.8 | O23: =+O24+O37+O43+O60+O91 -> 17529.17
B24: OE.2.1 | C24: MOVIMIENTO DE TIERRAS | K24: =+K25+K27+K30+K33+K35 -> 84163.16 | M24: =+M25+M27+M30+M33+M35 -> 84339.37 | O24: =+O25+O27+O30+O33+O35 -> 176.21
B25: OE.2.1.1 | C25: EXCAVACIONES MASIVA | K25: =SUM(K26) -> 5535.71 | M25: =SUM(M26) -> 5594.6 | O25: =SUM(O26) -> 58.89
B26: OE.2.1.1.1 | C26: Excavacion con maquinaria | D26: m3 | E26: 1177.81 | I26: =SUM(E26:H26) -> 1177.81 | J26: 4.7 | K26: =+ROUND(+IF(I26="",0,I26*J26),2) -> 5535.71 | L26: 4.75 | M26: =+ROUND(+IF(I26="",0,I26*L26),2) -> 5594.6 | N26: =+L26-J26 -> 0.05 | O26: =+M26-K26 -> 58.89
B27: OE.2.1.2 | C27: EXCAVACIONES | K27: =SUM(K28:K29)/2 -> 1877.45 | M27: =SUM(M28:M29)/2 -> 1948.94 | O27: =SUM(O28:O29)/2 -> 71.49
B28: OE.2.1.2.1 | C28: EXCAVACIONES SIMPLES | K28: =SUM(K29) -> 1877.45 | M28: =SUM(M29) -> 1948.94 | O28: =SUM(O29) -> 71.49
B29: OE.2.1.2.1.1 | C29: Excavacion manual de zanjas para Zapatas | D29: m3 | E29: 44.68 | I29: =SUM(E29:H29) -> 44.68 | J29: 42.02 | K29: =+ROUND(+IF(I29="",0,I29*J29),2) -> 1877.45 | L29: 43.62 | M29: =+ROUND(+IF(I29="",0,I29*L29),2) -> 1948.94 | N29: =+L29-J29 -> 1.6 | O29: =+M29-K29 -> 71.49
B30: OE.2.1.4 | C30: RELLENOS | K30: =SUM(K31:K32) -> 2989.14 | M30: =SUM(M31:M32) -> 2990.92 | O30: =SUM(O31:O32) -> 1.78
B31: OE.2.1.4.1 | C31: Relleno compactado con material de prestamo | D31: m3 | E31: 7 | I31: =SUM(E31:H31) -> 7 | J31: 65.58 | K31: =+ROUND(+IF(I31="",0,I31*J31),2) -> 459.06 | L31: 65.58 | M31: =+ROUND(+IF(I31="",0,I31*L31),2) -> 459.06 | N31: =+L31-J31 -> 0 | O31: =+M31-K31 -> 0
B32: OE.2.1.4.2 | C32: Relleno compactado c/equipo con material de afirmado e=0.15m | D32: m2 | E32: 178.3 | I32: =SUM(E32:H32) -> 178.3 | J32: 14.19 | K32: =+ROUND(+IF(I32="",0,I32*J32),2) -> 2530.08 | L32: 14.2 | M32: =+ROUND(+IF(I32="",0,I32*L32),2) -> 2531.86 | N32: =+L32-J32 -> 0.01 | O32: =+M32-K32 -> 1.78
B33: OE.2.1.5. | C33: NIVELACION INTERIOR Y APISONADO | K33: =SUM(K34) -> 299.88 | M33: =SUM(M34) -> 310.74 | O33: =SUM(O34) -> 10.86
B34: OE.2.1.5.1 | C34: Nivelacion interior y apisonado para f.piso,patio y veredas | D34: m2 | E34: 68 | I34: =SUM(E34:H34) -> 68 | J34: 4.41 | K34: =+ROUND(+IF(I34="",0,I34*J34),2) -> 299.88 | L34: 4.56968 | M34: =+ROUND(+IF(I34="",0,I34*L34),2) -> 310.74 | N34: =+L34-J34 -> 0.15968 | O34: =+M34-K34 -> 10.86
B35: OE.2.1.6 | C35: ELIMINACION DE MATERIAL EXCEDENTE | K35: =SUM(K36) -> 73460.98 | M35: =SUM(M36) -> 73494.17 | O35: =SUM(O36) -> 33.19
B36: OE.2.1.6.2 | C36: Eliminacion de material excedente con maquinaria | D36: m3 | E36: 1659.76 | I36: =SUM(E36:H36) -> 1659.76 | J36: 44.26 | K36: =+ROUND(+IF(I36="",0,I36*J36),2) -> 73460.98 | L36: 44.28 | M36: =+ROUND(+IF(I36="",0,I36*L36),2) -> 73494.17 | N36: =+L36-J36 -> 0.02 | O36: =+M36-K36 -> 33.19
B37: OE.2.2 | C37: OBRAS DE CONCRETO SIMPLE | K37: =+K38+K40 -> 12830.19 | M37: =+M38+M40 -> 13003.48 | O37: =+O38+O40 -> 173.29
B38: OE.2.2.3 | C38: SOLADOS | K38: =SUM(K39) -> 5048.26 | M38: =SUM(M39) -> 5127.14 | O38: =SUM(O39) -> 78.88
B39: OE.2.2.3.1 | C39: Solado para zapata e=0.10m, f'c=100kg/cm2 | D39: m2 | E39: 117.73 | I39: =SUM(E39:H39) -> 117.73 | J39: 42.88 | K39: =+ROUND(+IF(I39="",0,I39*J39),2) -> 5048.26 | L39: 43.55 | M39: =+ROUND(+IF(I39="",0,I39*L39),2) -> 5127.14 | N39: =+L39-J39 -> 0.67 | O39: =+M39-K39 -> 78.88
B40: OE.2.2.4 | C40: DADOS DE ANCLAJE | K40: =SUM(K41:K42) -> 7781.93 | M40: =SUM(M41:M42) -> 7876.34 | O40: =SUM(O41:O42) -> 94.41
B41: OE.2.2.4.1 | C41: Dado de anclaje f'c= 210 kg/cm2 | D41: und | F41: 64 | I41: =SUM(E41:H41) -> 64 | J41: 72.23 | K41: =+ROUND(+IF(I41="",0,I41*J41),2) -> 4622.72 | L41: 73.4 | M41: =+ROUND(+IF(I41="",0,I41*L41),2) -> 4697.6 | N41: =+L41-J41 -> 1.17 | O41: =+M41-K41 -> 74.88
B42: OE.2.2.4.2 | C42: Acero en dado de anclaje para cimientos de columna | D42: kg | F42: 93 | I42: =SUM(E42:H42) -> 93 | J42: 33.97 | K42: =+ROUND(+IF(I42="",0,I42*J42),2) -> 3159.21 | L42: 34.18 | M42: =+ROUND(+IF(I42="",0,I42*L42),2) -> 3178.74 | N42: =+L42-J42 -> 0.21 | O42: =+M42-K42 -> 19.53
B43: OE.2.3 | C43: OBRAS DE CONCRETO ARMADO | K43: =+K44+K49+K53+K57 -> 108194.24 | M43: =+M44+M49+M53+M57 -> 109731.15 | O43: =+O44+O49+O53+O57 -> 1536.91
B44: OE.2.3.9 | C44: LOSAS | K44: =SUM(K45:K48)/2 -> 38462.36 | M44: =SUM(M45:M48)/2 -> 38731.88 | O44: =SUM(O45:O48)/2 -> 269.52
B45: OE.2.3.9.8 | C45: LOSAS DE CONCRETO | K45: =SUM(K46:K48) -> 38462.36 | M45: =SUM(M46:M48) -> 38731.88 | O45: =SUM(O46:O48) -> 269.52
...

Sheet Var. MO-2 (2)
B1: |
B5: UNIDAD EJECUTORA | C5: : GERENCIA REGIONAL DE GESTION DE INVERSIONES DE INFRAESTRUCTURA - GOBIERNO REGIONAL CUSCO (SEDE CENTRAL)
B6: OBRA | C6: : MEJORAMIENTO Y AMPLIACION DE LOS SERVICIOS DE SALUD DEL ESTABLECIMIENTO DE SALUD DE BELEMPAMPA - DISTRITO DE SANTIAGO - PROVINCIA DE CUSCO - REGION CUSCO
B7: META | C7: : 0119-2025
B9: VARIACION DE MANO DE OBRA N°5
B11: Item | C11: DESCRIPCION | D11: Und | E11: Metrado Expediente | F11: PN1 | G11: MM1 | H11: DD1 | I11: Metrado Actual | J11: P.U. Expediente | K11: Parcial Expediente | L11: P.U. Actualizado | M11: Parcial Actualizado | N11: Diferencia P.U. | O11: Diferencia Parcial | Q11: MM4 | R11: DD4 | S11: MM5 | T11: DD5
A12: x | C12: COMPONENTE 01: SUFICIENTE Y ADECUADA INFRAESTRUCTURA Y MANTENIMIENTO PARA LA PRESTACIÓN DE SERVICIOS DE SALUD | K12: =+K13+K26+K113+K247+K424+K621+K712+K759 -> 5393725.7 | M12: =+M13+M26+M113+M247+M424+M621+M712+M759 -> 5446984 | O12: =+O13+O26+O113+O247+O424+O621+O712+O759 -> 53258.29 | Q12: =+#REF!+Q45+Q309+Q619+#REF!+#REF!+#REF!+#REF! -> #REF! | R12: =+#REF!+R45+R309+R619+#REF!+#REF!+#REF!+#REF! -> #REF! | S12: =+#REF!+S45+S309+S619+#REF!+#REF!+#REF!+#REF! -> #REF! | T12: =+#REF!+T45+T309+T619+#REF!+#REF!+#REF!+#REF! -> #REF!
A13: X | B13: OE.1 | C13: OBRAS PROVISIONALES, TRABAJOS PRELIMINARES, SEGURIDAD Y SALUD. | K13: =+K14+K23 -> 41472.9 | M13: =+M14+M23 -> 41924.51 | O13: =+O14+O23 -> 451.61
B14: OE.1.1 | C14: OBRAS PROVISIONALES Y TRABAJOS PRELIMINARES | K14: =+K15+K21 -> 30972.9 | M14: =+M15+M21 -> 31424.51 | O14: =+O15+O21 -> 451.61
B15: OE.1.1.3 | C15: TRABAJOS PRELIMINARES | K15: =SUM(K16:K20)/2 -> 30356.89 | M15: =SUM(M16:M20)/2 -> 30805.35 | O15: =SUM(O16:O20)/2 -> 448.46
B16: OE.1.1.3.1 | C16: LIMPIEZA DE TERRENO | K16: =SUM(K17:K20) -> 30356.89 | M16: =SUM(M17:M20) -> 30805.35 | O16: =SUM(O17:O20) -> 448.46
B17: OE.1.1.3.1.2 | C17: Traslado de material en desuso d=100 m | D17: m3 | F17: 44 | I17: =SUM(E17:H17) -> 44 | J17: 40.45 | K17: =+ROUND(+IF(I17="",0,I17*J17),2) -> 1779.8 | L17: 42.1 | M17: =+ROUND(+IF(I17="",0,I17*L17),2) -> 1852.4 | N17: =+L17-J17 -> 1.65 | O17: =+M17-K17 -> 72.6
B18: OE.1.1.3.1.3 | C18: Limpieza de terreno | D18: m2 | F18: 23 | I18: =SUM(E18:H18) -> 23 | J18: 2.61 | K18: =+ROUND(+IF(I18="",0,I18*J18),2) -> 60.03 | L18: 2.75 | M18: =+ROUND(+IF(I18="",0,I18*L18),2) -> 63.25 | N18: =+L18-J18 -> 0.14 | O18: =+M18-K18 -> 3.22
B19: OE.1.1.3.1.4 | C19: Acarreo manual de material de desmonte | D19: m3 | F19: 54 | I19: =SUM(E19:H19) -> 54 | J19: 25.21 | K19: =+ROUND(+IF(I19="",0,I19*J19),2) -> 1361.34 | L19: 26.17 | M19: =+ROUND(+IF(I19="",0,I19*L19),2) -> 1413.18 | N19: =+L19-J19 -> 0.96 | O19: =+M19-K19 -> 51.84
B20: OE.1.1.3.1.5 | C20: Eliminacion de desmonte con maquinaria | D20: m3 | F20: 802 | I20: =SUM(E20:H20) -> 802 | J20: 33.86 | K20: =+ROUND(+IF(I20="",0,I20*J20),2) -> 27155.72 | L20: 34.26 | M20: =+ROUND(+IF(I20="",0,I20*L20),2) -> 27476.52 | N20: =+L20-J20 -> 0.4 | O20: =+M20-K20 -> 320.8
B21: OE.1.1.9 | C21: TRAZOS, NIVELES Y REPLANTEO | K21: =SUM(K22) -> 616.01 | M21: =SUM(M22) -> 619.16 | O21: =SUM(O22) -> 3.15
B22: OE.1.1.9.2 | C22: Trazo y Replanteo durante el proceso | D22: m2 | E22: 157.95 | I22: =SUM(E22:H22) -> 157.95 | J22: 3.9 | K22: =+ROUND(+IF(I22="",0,I22*J22),2) -> 616.01 | L22: 3.92 | M22: =+ROUND(+IF(I22="",0,I22*L22),2) -> 619.16 | N22: =+L22-J22 -> 0.02 | O22: =+M22-K22 -> 3.15
B23: OE.1.2 | C23: SEGURIDAD Y SALUD | K23: =+K24 -> 10500 | M23: =+M24 -> 10500 | O23: =+O24 -> 0
B24: OE.1.2.3 | C24: PLAN PARA LA VIGILANCIA PREVENCION Y CONTROL DE COVID EN EL TRABAJO | K24: =SUM(K25) -> 10500 | M24: =SUM(M25) -> 10500 | O24: =SUM(O25) -> 0
B25: OE.1.2.3.5 | C25: Servicio de Pruebas COVID - 19 | D25: und | E25: 60 | I25: =SUM(E25:H25) -> 60 | J25: 175 | K25: =+ROUND(+IF(I25="",0,I25*J25),2) -> 10500 | L25: 175 | M25: =+ROUND(+IF(I25="",0,I25*L25),2) -> 10500 | N25: =+L25-J25 -> 0 | O25: =+M25-K25 -> 0
A26: X | B26: OE.2 | C26: ESTRUCTURAS. | K26: =+K27+K40+K46+K63+K94 -> 1595735.2 | M26: =+M27+M40+M46+M63+M94 -> 1613832 | O26: =+O27+O40+O46+O63+O94 -> 18096.81
B27: OE.2.1 | C27: MOVIMIENTO DE TIERRAS | K27: =+K28+K30+K33+K36+K38 -> 84163.16 | M27: =+M28+M30+M33+M36+M38 -> 84339.37 | O27: =+O28+O30+O33+O36+O38 -> 176.21
B28: OE.2.1.1 | C28: EXCAVACIONES MASIVA | K28: =SUM(K29) -> 5535.71 | M28: =SUM(M29) -> 5594.6 | O28: =SUM(O29) -> 58.89
B29: OE.2.1.1.1 | C29: Excavacion con maquinaria | D29: m3 | E29: 1177.81 | I29: =SUM(E29:H29) -> 1177.81 | J29: 4.7 | K29: =+ROUND(+IF(I29="",0,I29*J29),2) -> 5535.71 | L29: 4.75 | M29: =+ROUND(+IF(I29="",0,I29*L29),2) -> 5594.6 | N29: =+L29-J29 -> 0.05 | O29: =+M29-K29 -> 58.89
B30: OE.2.1.2 | C30: EXCAVACIONES | K30: =SUM(K31:K32)/2 -> 1877.45 | M30: =SUM(M31:M32)/2 -> 1948.94 | O30: =SUM(O31:O32)/2 -> 71.49
B31: OE.2.1.2.1 | C31: EXCAVACIONES SIMPLES | K31: =SUM(K32) -> 1877.45 | M31: =SUM(M32) -> 1948.94 | O31: =SUM(O32) -> 71.49
B32: OE.2.1.2.1.1 | C32: Excavacion manual de zanjas para Zapatas | D32: m3 | E32: 44.68 | I32: =SUM(E32:H32) -> 44.68 | J32: 42.02 | K32: =+ROUND(+IF(I32="",0,I32*J32),2) -> 1877.45 | L32: 43.62 | M32: =+ROUND(+IF(I32="",0,I32*L32),2) -> 1948.94 | N32: =+L32-J32 -> 1.6 | O32: =+M32-K32 -> 71.49
B33: OE.2.1.4 | C33: RELLENOS | K33: =SUM(K34:K35) -> 2989.14 | M33: =SUM(M34:M35) -> 2990.92 | O33: =SUM(O34:O35) -> 1.78
B34: OE.2.1.4.1 | C34: Relleno compactado con material de prestamo | D34: m3 | E34: 7 | I34: =SUM(E34:H34) -> 7 | J34: 65.58 | K34: =+ROUND(+IF(I34="",0,I34*J34),2) -> 459.06 | L34: 65.58 | M34: =+ROUND(+IF(I34="",0,I34*L34),2) -> 459.06 | N34: =+L34-J34 -> 0 | O34: =+M34-K34 -> 0
B35: OE.2.1.4.2 | C35: Relleno compactado c/equipo con material de afirmado e=0.15m | D35: m2 | E35: 178.3 | I35: =SUM(E35:H35) -> 178.3 | J35: 14.19 | K35: =+ROUND(+IF(I35="",0,I35*J35),2) -> 2530.08 | L35: 14.2 | M35: =+ROUND(+IF(I35="",0,I35*L35),2) -> 2531.86 | N35: =+L35-J35 -> 0.01 | O35: =+M35-K35 -> 1.78
B36: OE.2.1.5. | C36: NIVELACION INTERIOR Y APISONADO | K36: =SUM(K37) -> 299.88 | M36: =SUM(M37) -> 310.74 | O36: =SUM(O37) -> 10.86
B37: OE.2.1.5.1 | C37: Nivelacion interior y apisonado para f.piso,patio y veredas | D37: m2 | E37: 68 | I37: =SUM(E37:H37) -> 68 | J37: 4.41 | K37: =+ROUND(+IF(I37="",0,I37*J37),2) -> 299.88 | L37: 4.56968 | M37: =+ROUND(+IF(I37="",0,I37*L37),2) -> 310.74 | N37: =+L37-J37 -> 0.15968 | O37: =+M37-K37 -> 10.86
B38: OE.2.1.6 | C38: ELIMINACION DE MATERIAL EXCEDENTE | K38: =SUM(K39) -> 73460.98 | M38: =SUM(M39) -> 73494.17 | O38: =SUM(O39) -> 33.19
B39: OE.2.1.6.2 | C39: Eliminacion de material excedente con maquinaria | D39: m3 | E39: 1659.76 | I39: =SUM(E39:H39) -> 1659.76 | J39: 44.26 | K39: =+ROUND(+IF(I39="",0,I39*J39),2) -> 73460.98 | L39: 44.28 | M39: =+ROUND(+IF(I39="",0,I39*L39),2) -> 73494.17 | N39: =+L39-J39 -> 0.02 | O39: =+M39-K39 -> 33.19
B40: OE.2.2 | C40: OBRAS DE CONCRETO SIMPLE | K40: =+K41+K43 -> 12830.19 | M40: =+M41+M43 -> 13003.48 | O40: =+O41+O43 -> 173.29
B41: OE.2.2.3 | C41: SOLADOS | K41: =SUM(K42) -> 5048.26 | M41: =SUM(M42) -> 5127.14 | O41: =SUM(O42) -> 78.88
B42: OE.2.2.3.1 | C42: Solado para zapata e=0.10m, f'c=100kg/cm2 | D42: m2 | E42: 117.73 | I42: =SUM(E42:H42) -> 117.73 | J42: 42.88 | K42: =+ROUND(+IF(I42="",0,I42*J42),2) -> 5048.26 | L42: 43.55 | M42: =+ROUND(+IF(I42="",0,I42*L42),2) -> 5127.14 | N42: =+L42-J42 -> 0.67 | O42: =+M42-K42 -> 78.88
B43: OE.2.2.4 | C43: DADOS DE ANCLAJE | K43: =SUM(K44:K45) -> 7781.93 | M43: =SUM(M44:M45) -> 7876.34 | O43: =SUM(O44:O45) -> 94.41
B44: OE.2.2.4.1 | C44: Dado de anclaje f'c= 210 kg/cm2 | D44: und | F44: 64 | I44: =SUM(E44:H44) -> 64 | J44: 72.23 | K44: =+ROUND(+IF(I44="",0,I44*J44),2) -> 4622.72 | L44: 73.4 | M44: =+ROUND(+IF(I44="",0,I44*L44),2) -> 4697.6 | N44: =+L44-J44 -> 1.17 | O44: =+M44-K44 -> 74.88
B45: OE.2.2.4.2 | C45: Acero en dado de anclaje para cimientos de columna | D45: kg | F45: 93 | I45: =SUM(E45:H45) -> 93 | J45: 33.97 | K45: =+ROUND(+IF(I45="",0,I45*J45),2) -> 3159.21 | L45: 34.18 | M45: =+ROUND(+IF(I45="",0,I45*L45),2) -> 3178.74 | N45: =+L45-J45 -> 0.21 | O45: =+M45-K45 -> 19.53
...

Sheet DD-2
B1: |
B5: UNIDAD EJECUTORA | C5: : GERENCIA REGIONAL DE GESTION DE INVERSIONES DE INFRAESTRUCTURA - GOBIERNO REGIONAL CUSCO (SEDE CENTRAL)
B6: OBRA | C6: : MEJORAMIENTO Y AMPLIACION DE LOS SERVICIOS DE SALUD DEL ESTABLECIMIENTO DE SALUD DE BELEMPAMPA - DISTRITO DE SANTIAGO - PROVINCIA DE CUSCO - REGION CUSCO
B7: META | C7: : 0119-2025
B9: PARTIDAS DEDUCTIVOS N°04
B11: Item | C11: DESCRIPCION | D11: Und | E11: Metrado | F11: PU | G11: Parcial
B13: OE.3 | C13: ARQUITECTURA | G13: =+G14+G16+G20 -> 238275.81 | H13: X
B14: OE.3.3 | C14: CIELORRASOS | G14: =SUM(G15) -> 182063.62
B15: OE.3.3.6.4 | C15: Falso Cielorraso (Baldosa Translucida 0.61 x 0.61m) | D15: m2 | E15: 477.92 | F15: 380.95 | G15: =+ROUND(+IF(E15="",0,E15*F15),2) -> 182063.62
B16: OE.3.5 | C16: ZOCALOS Y CONTRAZOCALOS | G16: =+G17 -> 36219.35
B17: OE.3.5.2 | C17: CONTRAZOCALOS | G17: =SUM(G18:G19) -> 36219.35
B18: OE.3.5.2.11 | C18: OTROS
B19: OE.3.5.2.11.1 | C19: CONTRAZOCALO SANITARIO COVER FORMER H=0.10 M. | D19: m | E19: 1234.47 | F19: 29.34 | G19: =+ROUND(+IF(E19="",0,E19*F19),2) -> 36219.35
B20: OE.3.8 | C20: CARPINTERÍA METÁLICA Y HERRERÍA | G20: =+G21 -> 19992.84
B21: OE.3.8.14 | C21: BARANDA METALICA | G21: =SUM(G22:G22) -> 19992.84
B22: OE.3.8.14.1 | C22: BARANDAS METALICA EN ESCALERA PRINCIPAL H=1.17 m | D22: m | E22: 75.13 | F22: 266.11 | G22: =+ROUND(+IF(E22="",0,E22*F22),2) -> 19992.84
B23: TOTAL COSTO DIRECTO PARTIDAS DEDUCTIVOS N°04 | G23: =+G13 -> 238275.81

Sheet MM-3
B1: |
B5: UNIDAD EJECUTORA | C5: : GERENCIA REGIONAL DE GESTION DE INVERSIONES DE INFRAESTRUCTURA - GOBIERNO REGIONAL CUSCO (SEDE CENTRAL)
B6: OBRA | C6: : MEJORAMIENTO Y AMPLIACION DE LOS SERVICIOS DE SALUD DEL ESTABLECIMIENTO DE SALUD DE BELEMPAMPA - DISTRITO DE SANTIAGO - PROVINCIA DE CUSCO - REGION CUSCO
B7: META | C7: : 0119-2025
B9: MAYORES METRADOS N°03
B11: Item | C11: DESCRIPCION | D11: Und | E11: Metrado | F11: PU | G11: Parcial
B13: OE.1 | C13: OBRAS PROVISIONALES, TRABAJOS PRELIMINARES, SEGURIDAD Y SALUD. | G13: =+G14 -> 37042.77
B14: OE.1.1 | C14: OBRAS PROVISIONALES Y TRABAJOS PRELIMINARES | G14: =+G15+G18+G24 -> 37042.77
B15: OE.1.1.2 | C15: INSTALACIONES PROVISIONALES | G15: =SUM(G16:G17) -> 4304.87
B16: OE.1.1.2.3 | C16: Energia Electrica Provisional | D16: glb | E16: 1 | F16: 2837.67 | G16: =+ROUND(E16*F16,2) -> 2837.67
B17: OE.1.1.2.4 | C17: Abastecimiento Provisional de agua | D17: glb | E17: 1 | F17: 1467.2 | G17: =+ROUND(E17*F17,2) -> 1467.2
B18: OE.1.1.3 | C18: TRABAJOS PRELIMINARES | G18: =SUM(G19:G23)/2 -> 21565.9
B19: OE.1.1.3.1 | C19: LIMPIEZA DE TERRENO | G19: =SUM(G20:G23) -> 21565.9
B20: OE.1.1.3.1.1 | C20: Eliminación de maleza y arbustos de fácil extracción | D20: m2 | E20: 294 | F20: 13.45 | G20: =+ROUND(E20*F20,2) -> 3954.3
B21: OE.1.1.3.1.2 | C21: Traslado de materiales en desuso d=100 m | D21: m3 | E21: 248 | F21: 42.1 | G21: =+ROUND(E21*F21,2) -> 10440.8
B22: OE.1.1.3.1.3 | C22: Limpieza de terrreno | D22: m2 | E22: 1989 | F22: 2.75 | G22: =+ROUND(E22*F22,2) -> 5469.75
B23: OE.1.1.3.1.4 | C23: Acarreo manual de material de desmonte | D23: m3 | E23: 65 | F23: 26.17 | G23: =+ROUND(E23*F23,2) -> 1701.05
B24: OE.1.1.9 | C24: TRAZOS, NIVELES Y REPLANTEO | G24: =SUM(G25) -> 11172
B25: OE.1.1.9.2 | C25: Trazo y Replanteo durante el proceso | D25: m2 | E25: 2850 | F25: 3.92 | G25: =+ROUND(E25*F25,2) -> 11172
B26: OE.2 | C26: ESTRUCTURAS. | G26: =+G27 -> 283626.56
B27: OE.2.4 | C27: ESTRUCTURAS METÁLICAS | G27: =+G28+G32+G38 -> 283626.56
B28: OE.2.4.1 | C28: COLUMNAS METALICAS | G28: =SUM(G29:G31) -> 8034.17
B29: OE.2.4.1.1.7 | C29: Placa base Inc. Pernos de anclaje | D29: und | E29: 30 | F29: 161.35 | G29: =+ROUND(E29*F29,2) -> 4840.5
B30: OE.2.4.1.1.8 | C30: Armado Columnas metálicas | D30: kg | E30: 210.11 | F30: 11.52 | G30: =+ROUND(E30*F30,2) -> 2420.47
B31: OE.2.4.1.1.9 | C31: Montaje Columnas metálicas | D31: kg | E31: 210.11 | F31: 3.68 | G31: =+ROUND(E31*F31,2) -> 773.2
B32: OE.2.4.2 | C32: VIGAS METALICAS | G32: =SUM(G33:G37)/2 -> 144494.26
B33: OE.2.4.2.1 | C33: PARA ARMADO | G33: =SUM(G34) -> 103862.63
B34: OE.2.4.2.2.2.6 | C34: Armado de vigas metalicas | D34: m | E34: 500.76 | F34: 207.41 | G34: =+ROUND(E34*F34,2) -> 103862.63
B35: OE.2.4.2.3 | C35: PARA MONTAJE | G35: =SUM(G36:G37) -> 40631.63
B36: OE.2.4.2.2.2.5 | C36: Plancha Metálica Inc. Pernos de sujeción | D36: und | E36: 30 | F36: 137.04 | G36: =+ROUND(E36*F36,2) -> 4111.2
B37: OE.2.4.2.2.2.7 | C37: Montaje vigas metálicas | D37: m | E37: 500.76 | F37: 72.93 | G37: =+ROUND(E37*F37,2) -> 36520.43
B38: OE.2.4.3 | C38: TIJERALES METALICO | G38: =SUM(G39:G48)/2 -> 131098.13
B39: OE.2.4.3.2 | C39: Armado de Tijeral Metalico | G39: =SUM(G40:G43) -> 107158.43
B40: OE.2.4.3.2.2 | C40: Armado de Tijeral metálico Tipo 02 L=6.00 m | D40: und | E40: 35 | F40: 2113.18 | G40: =+ROUND(E40*F40,2) -> 73961.3
B41: OE.2.4.3.2.5 | C41: Armado de Tijeral metálico Tipo 05 L=3.00 m | D41: und | E41: 12 | F41: 1323.06 | G41: =+ROUND(E41*F41,2) -> 15876.72
B42: OE.2.4.3.2.6 | C42: Armado de Tijeral metálico Tipo 06 L=2.60 m | D42: und | E42: 11 | F42: 1245.06 | G42: =+ROUND(E42*F42,2) -> 13695.66
B43: OE.2.4.3.2.7 | C43: Armado de Tijeral metálico Tipo 07 L=1.90 m | D43: und | E43: 3 | F43: 1208.25 | G43: =+ROUND(E43*F43,2) -> 3624.75
B44: OE.2.4.3.3 | C44: Montaje de Tijeral Metalico | G44: =SUM(G45:G48) -> 23939.7
B45: OE.2.4.3.3.2 | C45: Montaje de Tijeral metálico Tipo 02 L=6.00 m | D45: und | E45: 35 | F45: 481.8 | G45: =+ROUND(E45*F45,2) -> 16863
B46: OE.2.4.3.3.5 | C46: Montaje de Tijeral metálico Tipo 05 L=3.00 m | D46: und | E46: 12 | F46: 335.31 | G46: =+ROUND(E46*F46,2) -> 4023.72
...

Sheet PN-3
B1: |
B5: UNIDAD EJECUTORA | C5: : GERENCIA REGIONAL DE GESTION DE INVERSIONES DE INFRAESTRUCTURA - GOBIERNO REGIONAL CUSCO (SEDE CENTRAL)
B6: OBRA | C6: : MEJORAMIENTO Y AMPLIACION DE LOS SERVICIOS DE SALUD DEL ESTABLECIMIENTO DE SALUD DE BELEMPAMPA - DISTRITO DE SANTIAGO - PROVINCIA DE CUSCO - REGION CUSCO
B7: META | C7: : 0119-2025
B9: PARTIDAS NUEVAS N°03
B11: Item | C11: DESCRIPCION | D11: Und | E11: Metrado | F11: PU | G11: Parcial
B13: OE.2 | C13: ESTRUCTURAS. | G13: =+G14+G20 -> 47896.24
B14: OE.2.4 | C14: ESTRUCTURAS METÁLICAS | G14: =+G15 -> 9997.84
B15: OE.2.4.4 | C15: TIJERALES METALICO | G15: =SUM(G16:G19)/2 -> 9997.84
B16: OE.2.4.4.1 | C16: ARMADO DE TIJERAL METALICO | G16: =SUM(G17) -> 7901.44
B17: OE.2.4.3.2.9 | C17: Armado de Tijeral metálico Tipo 09 L=3.70 m | D17: und | E17: 8 | F17: 987.68 | G17: =+ROUND(E17*F17,2) -> 7901.44
B18: OE.2.4.4.2 | C18: MONTAJE DE TIJERAL METALICO | G18: =SUM(G19) -> 2096.4
B19: OE.2.4.3.3.9 | C19: Montaje de Tijeral metálico Tipo 09 L=3.70 m | D19: und | E19: 8 | F19: 262.05 | G19: =+ROUND(E19*F19,2) -> 2096.4
B20: OE.2.6 | C20: VARIOS | G20: =+G21 -> 37898.4
B21: OE.2.6.1 | C21: ARRIOSTRAMIENTO METALICO | G21: =SUM(G22:G23) -> 37898.4
B22: OE.2.6.1.2 | C22: Plancha estriada de 1.20x2.40, e=1/8" | D22: und | E22: 18 | F22: 1093.5 | G22: =+ROUND(E22*F22,2) -> 19683
B23: OE.2.6.1.3 | C23: Parantes metalicos para contramarcos perfil 50x50x3.00mm | D23: und | E23: 140 | F23: 130.11 | G23: =+ROUND(E23*F23,2) -> 18215.4
B24: OE.3 | C24: ARQUITECTURA | G24: =+G25+G29+G32+G35+G39+G42+G62+G95+G102+G107+G111 -> 1041552.4
B25: OE.3.1 | C25: MUROS Y TABIQUES DE ALBAÑILERIA | G25: =+G26 -> 65076.12
B26: OE.3.1.10 | C26: MUROS CON EL SISTEMA DE CONSTRUCCIÓN EN SECO (SISTEMA DRY WALL O SIMILAR) | G26: =SUM(G27:G28) -> 65076.12
B27: OE.3.1.10.7 | C27: Recubrimiento de elementos estructurales con fibrocemento de 6mm | D27: m2 | E27: 163.24 | F27: 48.64 | G27: =+ROUND(E27*F27,2) -> 7939.99
B28: OE.3.1.10.8 | C28: Muro sistema de fibrocemento con lamina de plomo e=3mm | D28: m2 | E28: 44.8 | F28: 1275.36 | G28: =+ROUND(E28*F28,2) -> 57136.13
B29: OE.3.3 | C29: CIELORRASOS | G29: =+G30 -> 6334.46
B30: OE.3.3.6 | C30: FALSO CIELO RASO | G30: =SUM(G31) -> 6334.46
B31: OE.3.3.6.5 | C31: Falso cielo raso con placa superboard 6mm incluye estructuras | D31: m2 | E31: 32.01 | F31: 197.89 | G31: =+ROUND(E31*F31,2) -> 6334.46
B32: OE.3.4 | C32: PISOS Y PAVIMENTOS | G32: =+G33 -> 4551.13
B33: OE.3.4.2 | C33: PISOS | G33: =SUM(G34) -> 4551.13
B34: OE.3.4.2.28 | C34: Base de concreto para muebles fijos H=10cm | D34: m2 | E34: 21.93 | F34: 207.53 | G34: =+ROUND(E34*F34,2) -> 4551.13
B35: OE.3.5 | C35: ZOCALOS Y CONTRAZOCALOS | G35: =+G36 -> 23196.65
B36: OE.3.5.2 | C36: CONTRAZOCALOS | G36: =SUM(G37:G38)/2 -> 23196.65
B37: OE.3.5.2.3 | C37: CONTRAZOCALOS DE CERAMICO | G37: =SUM(G38) -> 23196.65
B38: OE.3.5.2.3.6 | C38: Contrazocalo de porcelanato H=10cm | D38: m | E38: 1001.15 | F38: 23.17 | G38: =+ROUND(E38*F38,2) -> 23196.65
B39: OE.3.6 | C39: COBERTURAS | G39: =+G40 -> 517674.47
B40: OE.3.6.7 | C40: RECUBRIMIENTOS SOBRE ESTRUCTURAS DE MADERA, METAL, ETC. | G40: =SUM(G41) -> 517674.47
B41: OE.3.6.7.7 | C41: Cobertura con termopaneles acusticos | D41: m2 | E41: 2538.74 | F41: 203.91 | G41: =+ROUND(E41*F41,2) -> 517674.47
B42: OE.3.7 | C42: CARPINTERIA DE MADERA | G42: =+G43+G60 -> 175630.01
B43: OE.3.7.1 | C43: PUERTAS | G43: =SUM(G44:G59) -> 145106.03
B44: OE.3.7.1.7 | C44: Puerta de 2 hojas vaiven contraplacada con plancha de acero (P-02) 1.40X2.70 m | D44: und | E44: 1 | F44: 1840.92 | G44: =+ROUND(E44*F44,2) -> 1840.92
B45: OE.3.7.1.8 | C45: Puerta de 2 hojas contraplacada (P-03) 1.80X2.70 m, según detalle | D45: und | E45: 1 | F45: 2325.92 | G45: =+ROUND(E45*F45,2) -> 2325.92
B46: OE.3.7.1.9 | C46: Puerta de 1 hoja contraplacada (P-05) 1.20X2.70 m, según detalle | D46: und | E46: 1 | F46: 1123.61 | G46: =+ROUND(E46*F46,2) -> 1123.61
...

Sheet DD-3
B1: |
B5: UNIDAD EJECUTORA | C5: : GERENCIA REGIONAL DE GESTION DE INVERSIONES DE INFRAESTRUCTURA - GOBIERNO REGIONAL CUSCO (SEDE CENTRAL)
B6: OBRA | C6: : MEJORAMIENTO Y AMPLIACION DE LOS SERVICIOS DE SALUD DEL ESTABLECIMIENTO DE SALUD DE BELEMPAMPA - DISTRITO DE SANTIAGO - PROVINCIA DE CUSCO - REGION CUSCO
B7: META | C7: : 0119-2025
B9: PARTIDAS DEDUCTIVOS N°3
B11: Item | C11: DESCRIPCION | D11: Und | E11: Metrado | F11: PU | G11: Parcial
B13: OE.1 | C13: OBRAS PROVISIONALES, TRABAJOS PRELIMINARES, SEGURIDAD Y SALUD. | G13: =+G14 -> 10500
B14: OE.1.1 | C14: OBRAS PROVISIONALES Y TRABAJOS PRELIMINARES | G14: =SUM(G15:G16) -> 10500
B15: OE.1.2.3 | C15: PLAN PARA LA VIGILANCIA PREVENCION Y CONTROL DE COVID EN EL TRABAJO
B16: OE.1.2.3.5 | C16: Servicio de Pruebas COVID - 19 | D16: und | E16: 60 | F16: 175 | G16: =+ROUND(+IF(E16="",0,E16*F16),2) -> 10500
B17: OE.2 | C17: ESTRUCTURAS. | G17: =+G18+G21+G25 -> 68180.18
B18: OE.2.1 | C18: MOVIMIENTO DE TIERRAS | G18: =SUM(G19:G20) -> 5535.71
B19: OE.2.1.1 | C19: EXCAVACIONES MASIVA
B20: OE.2.1.1.1 | C20: Excavacion con maquinaria | D20: m3 | E20: 1177.81 | F20: 4.7 | G20: =+ROUND(+IF(E20="",0,E20*F20),2) -> 5535.71
B21: OE.2.3 | C21: OBRAS DE CONCRETO ARMADO | G21: =SUM(G22:G24) -> 7759.7
B22: OE.2.3.12 | C22: CISTERNA
B23: OE.2.3.12.1 | C23: Cisternas -Concreto f´c=280kg/cm2 | D23: m3 | E23: 4.13 | F23: 661.41 | G23: =+ROUND(+IF(E23="",0,E23*F23),2) -> 2731.62
B24: OE.2.3.12.3 | C24: Cisternas -Acero fy=4200 kg/cm2 | D24: kg | E24: 700.29 | F24: 7.18 | G24: =+ROUND(+IF(E24="",0,E24*F24),2) -> 5028.08
B25: OE.2.6 | C25: VARIOS | G25: =SUM(G26:G33) -> 54884.77
B26: OE.2.6.1 | C26: ARRIOSTRAMIENTO METALICO
B27: OE.2.6.1.1 | C27: Arriostramiento metalico | D27: kg | E27: 3828.99 | F27: 12.24 | G27: =+ROUND(+IF(E27="",0,E27*F27),2) -> 46866.84
B28: OE.2.6.3 | C28: ARRIOSTRES DEL TECHO
B29: OE.2.6.3.1 | C29: Acero Ø 1/2" LISO | D29: m | E29: 492.2 | F29: 9.3 | G29: =+ROUND(+IF(E29="",0,E29*F29),2) -> 4577.46
B30: OE.2.6.3.2 | C30: Conexión de tirantes L64x64x7.9 | D30: m | E30: 8.67 | F30: 53.06 | G30: =+ROUND(+IF(E30="",0,E30*F30),2) -> 460.03
B31: OE.2.6.3.3 | C31: Angulo 2.5X2.5X3/16" | D31: m | E31: 30.08 | F31: 50.03 | G31: =+ROUND(+IF(E31="",0,E31*F31),2) -> 1504.9
B32: OE.2.6.5 | C32: CONTROL DE CALIDAD
B33: OE.2.6.5.1 | C33: Verificación de Capacidad Portante | D33: und | E33: 2 | F33: 737.77 | G33: =+ROUND(+IF(E33="",0,E33*F33),2) -> 1475.54
B34: OE.3 | C34: ARQUITECTURA | G34: =+G35+G38+G41+G49+G55+G75+G92+G101 -> 748266.79
B35: OE.3.1 | C35: MUROS Y TABIQUES DE ALBAÑILERIA | G35: =SUM(G36:G37) -> 33732.16
B36: OE.3.1.10 | C36: MUROS CON EL SISTEMA DE CONSTRUCCIÓN EN SECO (SISTEMA DRY WALL O SIMILAR)
B37: OE.3.1.10.3 | C37: MURO SISTEMA DRYWALL CON LAMINA DE PLOMO e=2mm | D37: m2 | E37: 44.8 | F37: 752.95 | G37: =+ROUND(+IF(E37="",0,E37*F37),2) -> 33732.16
B38: OE.3.3 | C38: CIELORRASOS | G38: =SUM(G39:G40) -> 13206.2
B39: OE.3.3.6 | C39: FALSO CIELO RASO
B40: OE.3.3.6.3 | C40: FALSO CIELO RASO CON PLACA DE SUPERBOARD CON LAMINA DE PLOMO e=2mm | D40: m2 | E40: 18.3 | F40: 721.65 | G40: =+ROUND(+IF(E40="",0,E40*F40),2) -> 13206.2
B41: OE.3.5 | C41: ZOCALOS Y CONTRAZOCALOS | G41: =SUM(G42:G48) -> 73769.41
B42: OE.3.5.1 | C42: ZOCALOS
A43: PN1 | B43: OE.3.5.1.13 | C43: Revestimiento Vinilico Conductivo | D43: m2 | E43: 37.4 | F43: 248.03 | G43: =+ROUND(+IF(E43="",0,E43*F43),2) -> 9276.32
B44: OE.3.5.2 | C44: CONTRAZOCALOS
B45: OE.3.5.2.3 | C45: CONTRAZOCALOS DE CERAMICO
A46: PN1 | B46: OE.3.5.2.3.3 | C46: Contrazocalo de ceramico (H=10cm) | D46: m | E46: 928.53 | F46: 30.45 | G46: =+ROUND(+IF(E46="",0,E46*F46),2) -> 28273.74
...

Sheet MM-4
B1: |
B5: UNIDAD EJECUTORA | C5: : GERENCIA REGIONAL DE GESTION DE INVERSIONES DE INFRAESTRUCTURA - GOBIERNO REGIONAL CUSCO (SEDE CENTRAL)
B6: OBRA | C6: : MEJORAMIENTO Y AMPLIACION DE LOS SERVICIOS DE SALUD DEL ESTABLECIMIENTO DE SALUD DE BELEMPAMPA - DISTRITO DE SANTIAGO - PROVINCIA DE CUSCO - REGION CUSCO
B7: META | C7: : 0119-2025
B9: PARTIDAS MAYORES METRADOS N°04
B11: Item | C11: DESCRIPCION | D11: Und | E11: Metrado | F11: PU | G11: Parcial
B12: OE.1 | C12: OBRAS PROVISIONALES, TRABAJOS PRELIMINARES, SEGURIDAD Y SALUD. | G12: =+G13 -> 1047034.9
B13: OE.1.1 | C13: OBRAS PROVISIONALES Y TRABAJOS PRELIMINARES | G13: =+G14+G21+G24+G31 -> 1047034.9
B14: OE.1.1.1 | C14: CONSTRUCCIONES PROVISIONALES | G14: =SUM(G15:G20) -> 755277.07
B15: OE.1.1.1.1 | C15: Oficinas | D15: m² | E15: 800 | F15: 157.37 | G15: =+ROUND(E15*F15,2) -> 125896
B16: OE.1.1.1.2 | C16: Almacenes | D16: m² | E16: 4148.09 | F16: 109.44 | G16: =+ROUND(E16*F16,2) -> 453966.97
B17: OE.1.1.1.3 | C17: Casetas de guardianÍa | D17: m² | E17: =28.79+12.27 -> 41.06 | F17: 147.84 | G17: =+ROUND(E17*F17,2) -> 6070.31
B18: OE.1.1.1.5 | C18: Vestuarios | D18: m² | E18: 680 | F18: 130.85 | G18: =+ROUND(E18*F18,2) -> 88978
B19: OE.1.1.1.6 | C19: Servicios higienicos | D19: m² | E19: 96 | F19: 282.01 | G19: =+ROUND(E19*F19,2) -> 27072.96
B20: OE.1.1.1.7 | C20: Cercos Provisional de calamina | D20: m | E20: =924.78+73.4 -> 998.18 | F20: 53.39 | G20: =+ROUND(E20*F20,2) -> 53292.83
B21: OE.1.1.4 | C21: ELIMINACION DE OBSTRUCCIONES | G21: =SUM(G22:G23) -> 1109.09
