Workbook

Sheet Datos
A1: fecha_ingreso | B1: Columna1 | C1: Columna2 | D1: dni | E1: nombre | F1: sexo | G1: especialidad | H1: cuadrilla | I1: categoria | J1: telefono | K1: condicion | L1: oficio
A2: 2024-02-01 | B2: 46100 | C2: =DATEDIF(Datos!$A2,Datos!$B2, "m") -> 25 | D2: 46473384 | E2: BOCANGELINO QUISPE, MICHEL | F2: M | I2: OFICIAL II | J2: 958734845 | K2: OBRERO | L2: DRYWALL-DRYWALL
A3: 2024-02-01 | B3: 46100 | C3: =DATEDIF(Datos!$A3,Datos!$B3, "m") -> 25 | D3: 23946320 | E3: CJUNO ALLPACA, ROSA | F3: F | I3: PEON II | J3: 954782913 | K3: OBRERO | L3: CONCRETO-CONCRETO
A4: 2024-02-01 | B4: 46100 | C4: =DATEDIF(Datos!$A4,Datos!$B4, "m") -> 25 | D4: 46927379 | E4: FERNANDEZ MOLINA, YOHEL DAVID | F4: M | I4: OFICIAL II | J4: 983106900 | K4: OBRERO | L4: DRYWALL-DRYWALL
A5: 2024-02-01 | B5: 46100 | C5: =DATEDIF(Datos!$A5,Datos!$B5, "m") -> 25 | D5: 44721474 | E5: ZAMATA PUCYURA, BRAULIO | F5: M | I5: PEON II | J5: 975037039 | K5: OBRERO | L5: GUARDIAN-GUARDIAN
A6: 2024-02-10 | B6: 46100 | C6: =DATEDIF(Datos!$A6,Datos!$B6, "m") -> 25 | D6: 44211561 | E6: OTAZU ORTIZ, WASHINGTON | F6: M | I6: OPERARIO II | J6: 925365987 | K6: OBRERO | L6: CONCRETO-CONCRETO
A7: 2024-02-10 | B7: 46100 | C7: =DATEDIF(Datos!$A7,Datos!$B7, "m") -> 25 | D7: 42308104 | E7: YANA HUILLCA, EXALTACION | F7: M | I7: OPERARIO II | J7: 948109276 | K7: OBRERO | L7: GASFITERIA-GASFITERIA
A8: 2024-05-01 | B8: 46100 | C8: =DATEDIF(Datos!$A8,Datos!$B8, "m") -> 22 | D8: 23835300 | E8: ÑAHUI CHUMBES, FRANCISCO | F8: M | I8: OPERARIO II | J8: 980435524 | K8: OBRERO | L8: CARPINTERO-CARPINTERO
A9: 2024-06-01 | B9: 46100 | C9: =DATEDIF(Datos!$A9,Datos!$B9, "m") -> 21 | D9: 77822340 | E9: DE LA TORRE JIMENEZ, JULINHO JUAN | F9: M | I9: OPERARIO II | J9: 992283527 | K9: OBRERO | L9: SOLDADURA-SOLDADURA
A10: 2024-06-01 | B10: 46100 | C10: =DATEDIF(Datos!$A10,Datos!$B10, "m") -> 21 | D10: 24004763 | E10: PORCEL GUTIERREZ, EDILBERTO | F10: M | I10: OPERARIO II | J10: 925018016 | K10: OBRERO | L10: ENCHAPADO-ENCHAPADO
A11: 2024-06-01 | B11: 46100 | C11: =DATEDIF(Datos!$A11,Datos!$B11, "m") -> 21 | D11: 43899124 | E11: QUIÑONEZ HUILLCA, SORAIDA | F11: F | I11: PEON II | J11: 987540629 | K11: OBRERO | L11: VIGIA-VIGIA
A12: 2024-06-10 | B12: 46100 | C12: =DATEDIF(Datos!$A12,Datos!$B12, "m") -> 21 | D12: 45439429 | E12: MANDURA CRISPIN, MARLENI | F12: F | I12: OFICIAL II | J12: 979359381 | K12: OBRERO | L12: ELECTROMECÁNICO-ELECTROMECÁNICO
A13: 2024-06-16 | B13: 46100 | C13: =DATEDIF(Datos!$A13,Datos!$B13, "m") -> 21 | D13: 24004025 | E13: JARA CHURA, CARLOS ENRIQUE | F13: M | I13: PEON II | J13: 945871523 | K13: OBRERO | L13: GUARDIAN-GUARDIAN
... A503: 2025-12-01 | B503: 46100 | C503: =DATEDIF(Datos!$A503,Datos!$B503, "m") -> 3 | D503: 44536570 | E503: TTITO HUAMANI, DINA | F503: F | I503: OFICIAL II | J503: 929959524 | K503: OBRERO | L503: ENCHAPADO-ENCHAPADO
A504: 2025-12-01 | B504: 46100 | C504: =DATEDIF(Datos!$A504,Datos!$B504, "m") -> 3 | D504: 74147574 | E504: URQUIZO OCHOA, DAYANA ALEJANDRA | F504: F | I504: PEON II | J504: 977863773 | K504: OBRERO | L504: CADISTA-CADISTA
A505: 2025-12-02 | B505: 46100 | C505: =DATEDIF(Datos!$A505,Datos!$B505, "m") -> 3 | D505: 73354600 | E505: HUAMANI VELILLE, MARCO ANTONIO | F505: M | I505: OFICIAL II | J505: 921899369 | K505: OBRERO | L505: TICS-TICS
A506: 2025-12-02 | B506: 46100 | C506: =DATEDIF(Datos!$A506,Datos!$B506, "m") -> 3 | D506: 73883519 | E506: QUISPE LAYME, LUZ ERIKA | F506: F | I506: OFICIAL II | J506: 931831600 | K506: OBRERO | L506: ALMACEN-ALMACEN
A507: 2025-12-02 | B507: 46100 | C507: =DATEDIF(Datos!$A507,Datos!$B507, "m") -> 3 | D507: 70048021 | E507: RUELAS PANTIGOSO, KEVIN JUAN | F507: M | I507: OFICIAL II | J507: 972269433 | K507: OBRERO | L507: ALMACEN-ALMACEN
A508: 2025-12-02 | B508: 46100 | C508: =DATEDIF(Datos!$A508,Datos!$B508, "m") -> 3 | D508: 72724463 | E508: SANTA CRUZ CHACON, DANA NICOL | F508: F | I508: OFICIAL II | J508: 910444505 | K508: OBRERO | L508: ALMACEN-ALMACEN
A509: 2025-12-03 | B509: 46100 | C509: =DATEDIF(Datos!$A509,Datos!$B509, "m") -> 3 | D509: 47197144 | E509: GALLEGOS VITORINO, PAUL EDGAR | F509: M | I509: OFICIAL II | J509: 930247166 | K509: OBRERO | L509: ALMACEN-ALMACEN
A510: 2025-12-03 | B510: 46100 | C510: =DATEDIF(Datos!$A510,Datos!$B510, "m") -> 3 | D510: 48331511 | E510: LAIME ANTITUPA, NAHUN | F510: M | I510: OPERARIO II | J510: 901369683 | K510: OBRERO | L510: SANITARIO-SANITARIO
A511: 2025-12-03 | B511: 46100 | C511: =DATEDIF(Datos!$A511,Datos!$B511, "m") -> 3 | D511: 42609013 | E511: QUISPE CASTRO, ALEX CESAR | F511: M | I511: OPERARIO II | J511: 939057201 | K511: OBRERO | L511: DRYWALL-DRYWALL
A512: 2025-12-03 | B512: 46100 | C512: =DATEDIF(Datos!$A512,Datos!$B512, "m") -> 3 | D512: 73860477 | E512: SILVA MOLLEHUANCA, VICTOR RENZO | F512: M | I512: OFICIAL II | J512: 969378717 | K512: OBRERO | L512: ALMACEN-ALMACEN
A513: 2025-12-04 | B513: 46100 | C513: =DATEDIF(Datos!$A513,Datos!$B513, "m") -> 3 | D513: 77906818 | E513: HUAMAN HUAMAN, DARIO | F513: M | I513: OPERARIO II | J513: 959623013 | K513: OBRERO | L513: SOLDADURA-SOLDADURA
A514: 2025-12-05 | B514: 46100 | C514: =DATEDIF(Datos!$A514,Datos!$B514, "m") -> 3 | D514: 47226882 | E514: AQUICE CHUNCHO, ABEL | F514: M | I514: OFICIAL II | J514: 906519392 | K514: OBRERO | L514: SOLDADURA-SOLDADURA
A515: 2025-12-05 | B515: 46100 | C515: =DATEDIF(Datos!$A515,Datos!$B515, "m") -> 3 | D515: 43316168 | E515: HUAMANI RAMOS, AMILCAR ROBERTO | F515: M | I515: OPERARIO II | J515: 901609110 | K515: OBRERO | L515: SOLDADURA-SOLDADURA
A516: 2025-12-06 | B516: 46100 | C516: =DATEDIF(Datos!$A516,Datos!$B516, "m") -> 3 | D516: 43612784 | E516: LUNA HUAYPAMAYTA, CESAR AUGUSTO | F516: M | I516: OFICIAL II | J516: 974255233 | K516: OBRERO | L516: PINTURA-PINTURA
... A630: 2026-02-06 | B630: 46100 | C630: =DATEDIF(Datos!$A630,Datos!$B630, "m") -> 1 | D630: 77907631 | E630: SANCHEZ RIVERA, SEBASTIAN | F630: M | I630: OFICIAL II | J630: 945438414 | K630: OBRERO | L630: DRYWALL-DRYWALL
A631: 2026-02-07 | B631: 46100 | C631: =DATEDIF(Datos!$A631,Datos!$B631, "m") -> 1 | D631: 72143832 | E631: CCASA QUISPE, DAYANA | F631: F | I631: PEON II | J631: 903059977 | K631: OBRERO | L631: GUARDIAN-GUARDIAN
A632: 2026-02-09 | B632: 46100 | C632: =DATEDIF(Datos!$A632,Datos!$B632, "m") -> 1 | D632: 24805390 | E632: ANCALLA MALDONADO, ADOLFO NIEVES | F632: M | I632: PEON II | J632: 927105263 | K632: OBRERO | L632: VOLANTE DE APOYO-VOLANTE DE APOYO
A633: 2026-02-09 | B633: 46100 | C633: =DATEDIF(Datos!$A633,Datos!$B633, "m") -> 1 | D633: 80206977 | E633: ANGULO TORRES, JUSTO | F633: M | I633: OPERARIO II | J633: 928250215 | K633: OBRERO | L633: DRYWALL-DRYWALL
A634: 2026-02-09 | B634: 46100 | C634: =DATEDIF(Datos!$A634,Datos!$B634, "m") -> 1 | D634: 73662312 | E634: JALLASI CCOYA, CARLITA SONIA | F634: F | I634: PEON II | J634: 970112853 | K634: OBRERO | L634: VOLANTE DE APOYO-VOLANTE DE APOYO
A635: 2026-02-09 | B635: 46100 | C635: =DATEDIF(Datos!$A635,Datos!$B635, "m") -> 1 | D635: 43975778 | E635: SAIRE SOTO, EULALIA | F635: M | I635: PEON II | K635: OBRERO | L635: ENCHAPADO-ENCHAPADO
A636: 2026-02-09 | B636: 46100 | C636: =DATEDIF(Datos!$A636,Datos!$B636, "m") -> 1 | D636: 44735235 | E636: TTITO SUMINA, NOIMI | F636: F | I636: PEON II | J636: 935110922 | K636: OBRERO | L636: ENCHAPADO-ENCHAPADO
A637: 2026-02-09 | B637: 46100 | C637: =DATEDIF(Datos!$A637,Datos!$B637, "m") -> 1 | D637: 25061315 | E637: VILLA DURAN, BERNARDINO | F637: M | I637: OPERARIO II | J637: 962216908 | K637: OBRERO | L637: ALBAÑIL-ALBAÑIL
A638: 2026-02-10 | B638: 46100 | C638: =DATEDIF(Datos!$A638,Datos!$B638, "m") -> 1 | D638: 42210467 | E638: AYERBE VALDIVIA, TANIA | F638: F | I638: PEON II | J638: 962396732 | K638: OBRERO | L638: ALMACEN-ALMACEN
A639: 2026-02-10 | B639: 46100 | C639: =DATEDIF(Datos!$A639,Datos!$B639, "m") -> 1 | D639: 25071931 | E639: BENAVENTE CARRASCO, DIEGO | F639: M | I639: OPERARIO II | J639: 935682321 | K639: OBRERO | L639: SANITARIO-SANITARIO
A640: 2026-02-10 | B640: 46100 | C640: =DATEDIF(Datos!$A640,Datos!$B640, "m") -> 1 | D640: 40205223 | E640: CARAZAS MORMONTOY, EDWIN DARIO | F640: M | I640: PEON II | J640: 964341084 | K640: OBRERO | L640: SANITARIO-SANITARIO
A641: 2026-02-10 | B641: 46100 | C641: =DATEDIF(Datos!$A641,Datos!$B641, "m") -> 1 | D641: 70375400 | E641: HUMPIRE HUAMAN, JOSETH PAOLO | F641: M | I641: OFICIAL II | J641: 953003437 | K641: OBRERO | L641: SANITARIO-SANITARIO
A642: 2026-02-10 | B642: 46100 | C642: =DATEDIF(Datos!$A642,Datos!$B642, "m") -> 1 | D642: 73861815 | E642: LEON HUAMAN, EDWIN RONNY | F642: M | I642: PEON II | J642: 914376759 | K642: OBRERO | L642: SANITARIO-SANITARIO
...
